Workbook

Sheet 00_README_METHODOLOGY
A1: Fresh Thyme YTD SLA Reporting Package — Methodology & QA Notes
A3: Scope & Source
A4: • Source file: Fresh_Thyme_Year_to_Date_08_01_2025.xlsx — one sheet, 569 ticket records, 227 source columns, covering closed dates Aug 1, 2025 through Aug 11, 2026.
A5: • This is NCR field-service ticket data for Meijer Inc. (Account Name), reported under the Fresh Thyme banner (69 store locations across 10 states). Service Request Type is predominantly 'MNT' (maintenance, 414 tickets) and 'CHGC' (149 tickets), with 6 'CHGF'.
A6: • 01_RAW_DATA is a verbatim, unedited copy of the source for audit and reconciliation. All analysis is built on 02_CLEAN_DATA, a derived layer that never modifies the original values.
A8: SLA Methodology — the core logic
A9: • This dataset carries two SLA layers for ticket resolution: a raw/gross determination made at ticket close, and a mitigation-adjusted determination applied afterward through a vendor exception-review process. Both are preserved and reported separately, as requested.
A10: • RAW SLA: uses 'Service Level Agreement Resolve Met Indicator' (source column DZ) — the ticket-level pass/fail against its Resolve Limit Duration, before any mitigation review. Reported on 08_RESOLUTION_ANALYSIS and as a comparison figure; overall raw attainment among SLA-eligible tickets is 342/435 = 78.6%.
A11: • SLA ELIGIBILITY / OPPORTUNITY: uses 'Service Level Agreement Resolve Opportunity Indicator' (source column EB) exactly as instructed. EB = 1 means the ticket counts toward the SLA population after mitigation review (435 of 569 tickets); EB = 0 means it is excluded from the opportunity population entirely (134 tickets) — this happens both for tickets that are structurally out of SLA scope and for tickets where an approved mitigation removed them from consideration.
A12: • FINAL / ADJUSTED SLA MET (what this report calls 'Adjusted / Opportunity SLA'): for every ticket where Opportunity = 1, we take the 'Mitigated Service Level Agreement Resolve Met Indicator' (source column CE) when it has been populated (i.e., a mitigation was fully processed — 'Mitigated Indicator' = 2), and fall back to the 'Service Level Agreement Resolve Met Net Indicator' (source column EA) when no mitigation outcome was recorded for that ticket. This is computed as a live formula in 02_CLEAN_DATA column V ('Final SLA Met') and labeled in column W ('Final SLA Result': Met / Missed / Not Eligible).
A13: • This logic was validated by grouping the full dataset on every combination of Mitigated Indicator, Mitigation Reason, the four SLA indicator fields (DZ/EA/EB/CE), Reviewed Indicator, Exclude flag and ticket status — 16 distinct combinations covering all 569 rows — and confirming the Final SLA Met formula reproduces a fully reconciled 337 Met / 98 Missed / 134 Not Eligible split (337+98+134 = 569).
A14: • YTD Adjusted/Opportunity SLA % = 337 ÷ 435 = 77.5%. This is the headline SLA metric used on the dashboard and throughout the PowerPoint.
... A42: • All PowerPoint figures are pulled from this recalculated workbook — no independently recomputed numbers.

Sheet 03_EXECUTIVE_DASHBOARD
A1: FRESH THYME — YTD OPERATIONS / SLA PERFORMANCE REPORT
A3: Field Service SLA Analysis | Period: Aug 2025 – Aug 2026 | Vendor: NCR | Account: Meijer Inc. (Fresh Thyme banner)
A5: TOTAL TICKETS | C5: CLOSED TICKETS | E5: OPEN TICKETS | G5: CANCELED TICKETS | I5: SLA ELIGIBLE TICKETS
A6: =COUNTA('02_CLEAN_DATA'!$A$2:$A$570) -> 569 | C6: =COUNTIF('02_CLEAN_DATA'!$M$2:$M$570,"closed") -> 561 | E6: =COUNTIF('02_CLEAN_DATA'!$M$2:$M$570,"open") -> 1 | G6: =COUNTIF('02_CLEAN_DATA'!$M$2:$M$570,"canceled*") -> 7 | I6: =COUNTIF('02_CLEAN_DATA'!$R$2:$R$570,1) -> 435
A10: SLA MET | C10: SLA MISSED | E10: YTD SLA % (ADJUSTED) | G10: SLA TARGET (INPUT) | I10: VARIANCE TO TARGET (PP)
A11: =COUNTIF('02_CLEAN_DATA'!$W$2:$W$570,"Met") -> 337 | C11: =COUNTIF('02_CLEAN_DATA'!$W$2:$W$570,"Missed") -> 98 | E11: =COUNTIF('02_CLEAN_DATA'!$W$2:$W$570,"Met")/COUNTIF('02_CLEAN_DATA'!$R$2:$R$570,1) -> 0.77471264 | G11: =IF(ISBLANK('04_SLA_TREND'!$B$1),"Not Set",'04_SLA_TREND'!$B$1) -> Not Set | I11: =IF(ISBLANK('04_SLA_TREND'!$B$1),"Enter target",E11-'04_SLA_TREND'!$B$1) -> Enter target
A15: EXCEPTIONS (CCR) | C15: EXCEPTION RATE | E15: AVG RESOLUTION TIME (HRS) | G15: MEDIAN RESOLUTION (HRS) | I15: EXCLUDED FROM OPPORTUNITY
A16: =COUNTIF('02_CLEAN_DATA'!$S$2:$S$570,"Customer Contracted Reasons") -> 353 | C16: =COUNTIF('02_CLEAN_DATA'!$S$2:$S$570,"Customer Contracted Reasons")/COUNTA('02_CLEAN_DATA'!$A$2:$A$570) -> 0.62038664 | E16: =AVERAGE('02_CLEAN_DATA'!$O$2:$O$570) -> 30.227606 | G16: {=MEDIAN('02_CLEAN_DATA'!$O$2:$O$570)} -> 14.04 | I16: =COUNTIF('02_CLEAN_DATA'!$R$2:$R$570,0) -> 134
A21: Color reference bands used throughout this workbook: | D21: ≥ 90% SLA | F21: 80–90% SLA | H21: < 80% SLA
A22: These are common field-service reporting bands, not a Fresh Thyme/Meijer contracted figure — no target % is present in the source data. Enter an actual contracted target in the SLA Target card above (linked to 04_SLA_TREND!B1) to activate variance-to-target reporting workbook-wide.
A25: YTD Monthly SLA % Trend (Adjusted / Opportunity Basis) | H25: Ticket Mix
A47: Methodology: SLA % = Final SLA Met ÷ SLA Eligible tickets (Service Level Agreement Resolve Opportunity Indicator = 1), where Final SLA Met uses the Mitigated SLA Resolve Met Indicator when a mitigation has been fully processed, otherwise the Net SLA Resolve Met Indicator. Full methodology, data-quality notes and assumptions are documented in 00_README_METHODOLOGY.

Sheet 04_SLA_TREND
A1: Contracted SLA Target % | C1: << Input cell: enter Fresh Thyme / Meijer's contracted SLA target here (e.g. 0.90) to activate variance-to-target reporting. No target % is present in the source workbook, so it is intentionally left blank rather than assumed.
A2: Month | B2: Total Tickets | C2: SLA Eligible | D2: SLA Met | E2: SLA Missed | F2: SLA % | G2: Variance to Target (pp) | H2: Exceptions (CCR) | I2: Exception Rate | J2: Avg Resolution (Hrs) | K2: Median Resolution (Hrs)
A3: 2025-08 | B3: =COUNTIF('02_CLEAN_DATA'!$L$2:$L$570,A3) -> 39 | C3: =COUNTIFS('02_CLEAN_DATA'!$L$2:$L$570,A3,'02_CLEAN_DATA'!$R$2:$R$570,1) -> 19 | D3: =COUNTIFS('02_CLEAN_DATA'!$L$2:$L$570,A3,'02_CLEAN_DATA'!$W$2:$W$570,"Met") -> 15 | E3: =COUNTIFS('02_CLEAN_DATA'!$L$2:$L$570,A3,'02_CLEAN_DATA'!$W$2:$W$570,"Missed") -> 4 | F3: =IF(C3=0,"",D3/C3) -> 0.78947368 | G3: =IF(OR($B$1="",F3=""),"",F3-$B$1) | H3: =COUNTIFS('02_CLEAN_DATA'!$L$2:$L$570,A3,'02_CLEAN_DATA'!$S$2:$S$570,"Customer Contracted Reasons") -> 3 | I3: =IF(B3=0,"",H3/B3) -> 0.076923077 | J3: =IFERROR(AVERAGEIF('02_CLEAN_DATA'!$L$2:$L$570,A3,'02_CLEAN_DATA'!$O$2:$O$570),"") -> 32.271282 | K3: {=IFERROR(MEDIAN(IF('02_CLEAN_DATA'!$L$2:$L$570=A3,'02_CLEAN_DATA'!$O$2:$O$570)),"")} -> 21.25
A4: 2025-09 | B4: =COUNTIF('02_CLEAN_DATA'!$L$2:$L$570,A4) -> 57 | C4: =COUNTIFS('02_CLEAN_DATA'!$L$2:$L$570,A4,'02_CLEAN_DATA'!$R$2:$R$570,1) -> 44 | D4: =COUNTIFS('02_CLEAN_DATA'!$L$2:$L$570,A4,'02_CLEAN_DATA'!$W$2:$W$570,"Met") -> 31 | E4: =COUNTIFS('02_CLEAN_DATA'!$L$2:$L$570,A4,'02_CLEAN_DATA'!$W$2:$W$570,"Missed") -> 13 | F4: =IF(C4=0,"",D4/C4) -> 0.70454545 | G4: =IF(OR($B$1="",F4=""),"",F4-$B$1) | H4: =COUNTIFS('02_CLEAN_DATA'!$L$2:$L$570,A4,'02_CLEAN_DATA'!$S$2:$S$570,"Customer Contracted Reasons") -> 11 | I4: =IF(B4=0,"",H4/B4) -> 0.19298246 | J4: =IFERROR(AVERAGEIF('02_CLEAN_DATA'!$L$2:$L$570,A4,'02_CLEAN_DATA'!$O$2:$O$570),"") -> 42.746316 | K4: {=IFERROR(MEDIAN(IF('02_CLEAN_DATA'!$L$2:$L$570=A4,'02_CLEAN_DATA'!$O$2:$O$570)),"")} -> 14.85
A5: 2025-10 | B5: =COUNTIF('02_CLEAN_DATA'!$L$2:$L$570,A5) -> 56 | C5: =COUNTIFS('02_CLEAN_DATA'!$L$2:$L$570,A5,'02_CLEAN_DATA'!$R$2:$R$570,1) -> 37 | D5: =COUNTIFS('02_CLEAN_DATA'!$L$2:$L$570,A5,'02_CLEAN_DATA'!$W$2:$W$570,"Met") -> 23 | E5: =COUNTIFS('02_CLEAN_DATA'!$L$2:$L$570,A5,'02_CLEAN_DATA'!$W$2:$W$570,"Missed") -> 14 | F5: =IF(C5=0,"",D5/C5) -> 0.62162162 | G5: =IF(OR($B$1="",F5=""),"",F5-$B$1) | H5: =COUNTIFS('02_CLEAN_DATA'!$L$2:$L$570,A5,'02_CLEAN_DATA'!$S$2:$S$570,"Customer Contracted Reasons") -> 7 | I5: =IF(B5=0,"",H5/B5) -> 0.125 | J5: =IFERROR(AVERAGEIF('02_CLEAN_DATA'!$L$2:$L$570,A5,'02_CLEAN_DATA'!$O$2:$O$570),"") -> 41.202321 | K5: {=IFERROR(MEDIAN(IF('02_CLEAN_DATA'!$L$2:$L$570=A5,'02_CLEAN_DATA'!$O$2:$O$570)),"")} -> 20.875
A6: 2025-11 | B6: =COUNTIF('02_CLEAN_DATA'!$L$2:$L$570,A6) -> 44 | C6: =COUNTIFS('02_CLEAN_DATA'!$L$2:$L$570,A6,'02_CLEAN_DATA'!$R$2:$R$570,1) -> 28 | D6: =COUNTIFS('02_CLEAN_DATA'!$L$2:$L$570,A6,'02_CLEAN_DATA'!$W$2:$W$570,"Met") -> 11 | E6: =COUNTIFS('02_CLEAN_DATA'!$L$2:$L$570,A6,'02_CLEAN_DATA'!$W$2:$W$570,"Missed") -> 17 | F6: =IF(C6=0,"",D6/C6) -> 0.39285714 | G6: =IF(OR($B$1="",F6=""),"",F6-$B$1) | H6: =COUNTIFS('02_CLEAN_DATA'!$L$2:$L$570,A6,'02_CLEAN_DATA'!$S$2:$S$570,"Customer Contracted Reasons") -> 5 | I6: =IF(B6=0,"",H6/B6) -> 0.11363636 | J6: =IFERROR(AVERAGEIF('02_CLEAN_DATA'!$L$2:$L$570,A6,'02_CLEAN_DATA'!$O$2:$O$570),"") -> 59.275227 | K6: {=IFERROR(MEDIAN(IF('02_CLEAN_DATA'!$L$2:$L$570=A6,'02_CLEAN_DATA'!$O$2:$O$570)),"")} -> 15.5
A7: 2025-12 | B7: =COUNTIF('02_CLEAN_DATA'!$L$2:$L$570,A7) -> 50 | C7: =COUNTIFS('02_CLEAN_DATA'!$L$2:$L$570,A7,'02_CLEAN_DATA'!$R$2:$R$570,1) -> 39 | D7: =COUNTIFS('02_CLEAN_DATA'!$L$2:$L$570,A7,'02_CLEAN_DATA'!$W$2:$W$570,"Met") -> 32 | E7: =COUNTIFS('02_CLEAN_DATA'!$L$2:$L$570,A7,'02_CLEAN_DATA'!$W$2:$W$570,"Missed") -> 7 | F7: =IF(C7=0,"",D7/C7) -> 0.82051282 | G7: =IF(OR($B$1="",F7=""),"",F7-$B$1) | H7: =COUNTIFS('02_CLEAN_DATA'!$L$2:$L$570,A7,'02_CLEAN_DATA'!$S$2:$S$570,"Customer Contracted Reasons") -> 8 | I7: =IF(B7=0,"",H7/B7) -> 0.16 | J7: =IFERROR(AVERAGEIF('02_CLEAN_DATA'!$L$2:$L$570,A7,'02_CLEAN_DATA'!$O$2:$O$570),"") -> 23.1098 | K7: {=IFERROR(MEDIAN(IF('02_CLEAN_DATA'!$L$2:$L$570=A7,'02_CLEAN_DATA'!$O$2:$O$570)),"")} -> 12.67
A8: 2026-01 | B8: =COUNTIF('02_CLEAN_DATA'!$L$2:$L$570,A8) -> 57 | C8: =COUNTIFS('02_CLEAN_DATA'!$L$2:$L$570,A8,'02_CLEAN_DATA'!$R$2:$R$570,1) -> 38 | D8: =COUNTIFS('02_CLEAN_DATA'!$L$2:$L$570,A8,'02_CLEAN_DATA'!$W$2:$W$570,"Met") -> 28 | E8: =COUNTIFS('02_CLEAN_DATA'!$L$2:$L$570,A8,'02_CLEAN_DATA'!$W$2:$W$570,"Missed") -> 10 | F8: =IF(C8=0,"",D8/C8) -> 0.73684211 | G8: =IF(OR($B$1="",F8=""),"",F8-$B$1) | H8: =COUNTIFS('02_CLEAN_DATA'!$L$2:$L$570,A8,'02_CLEAN_DATA'!$S$2:$S$570,"Customer Contracted Reasons") -> 57 | I8: =IF(B8=0,"",H8/B8) -> 1 | J8: =IFERROR(AVERAGEIF('02_CLEAN_DATA'!$L$2:$L$570,A8,'02_CLEAN_DATA'!$O$2:$O$570),"") -> 22.958246 | K8: {=IFERROR(MEDIAN(IF('02_CLEAN_DATA'!$L$2:$L$570=A8,'02_CLEAN_DATA'!$O$2:$O$570)),"")} -> 4.13
A9: 2026-02 | B9: =COUNTIF('02_CLEAN_DATA'!$L$2:$L$570,A9) -> 41 | C9: =COUNTIFS('02_CLEAN_DATA'!$L$2:$L$570,A9,'02_CLEAN_DATA'!$R$2:$R$570,1) -> 40 | D9: =COUNTIFS('02_CLEAN_DATA'!$L$2:$L$570,A9,'02_CLEAN_DATA'!$W$2:$W$570,"Met") -> 40 | E9: =COUNTIFS('02_CLEAN_DATA'!$L$2:$L$570,A9,'02_CLEAN_DATA'!$W$2:$W$570,"Missed") -> 0 | F9: =IF(C9=0,"",D9/C9) -> 1 | G9: =IF(OR($B$1="",F9=""),"",F9-$B$1) | H9: =COUNTIFS('02_CLEAN_DATA'!$L$2:$L$570,A9,'02_CLEAN_DATA'!$S$2:$S$570,"Customer Contracted Reasons") -> 41 | I9: =IF(B9=0,"",H9/B9) -> 1 | J9: =IFERROR(AVERAGEIF('02_CLEAN_DATA'!$L$2:$L$570,A9,'02_CLEAN_DATA'!$O$2:$O$570),"") -> 11.812439 | K9: {=IFERROR(MEDIAN(IF('02_CLEAN_DATA'!$L$2:$L$570=A9,'02_CLEAN_DATA'!$O$2:$O$570)),"")} -> 3.48
A10: 2026-03 | B10: =COUNTIF('02_CLEAN_DATA'!$L$2:$L$570,A10) -> 45 | C10: =COUNTIFS('02_CLEAN_DATA'!$L$2:$L$570,A10,'02_CLEAN_DATA'!$R$2:$R$570,1) -> 45 | D10: =COUNTIFS('02_CLEAN_DATA'!$L$2:$L$570,A10,'02_CLEAN_DATA'!$W$2:$W$570,"Met") -> 40 | E10: =COUNTIFS('02_CLEAN_DATA'!$L$2:$L$570,A10,'02_CLEAN_DATA'!$W$2:$W$570,"Missed") -> 5 | F10: =IF(C10=0,"",D10/C10) -> 0.88888889 | G10: =IF(OR($B$1="",F10=""),"",F10-$B$1) | H10: =COUNTIFS('02_CLEAN_DATA'!$L$2:$L$570,A10,'02_CLEAN_DATA'!$S$2:$S$570,"Customer Contracted Reasons") -> 45 | I10: =IF(B10=0,"",H10/B10) -> 1 | J10: =IFERROR(AVERAGEIF('02_CLEAN_DATA'!$L$2:$L$570,A10,'02_CLEAN_DATA'!$O$2:$O$570),"") -> 31.538889 | K10: {=IFERROR(MEDIAN(IF('02_CLEAN_DATA'!$L$2:$L$570=A10,'02_CLEAN_DATA'!$O$2:$O$570)),"")} -> 17.63
A11: 2026-04 | B11: =COUNTIF('02_CLEAN_DATA'!$L$2:$L$570,A11) -> 40 | C11: =COUNTIFS('02_CLEAN_DATA'!$L$2:$L$570,A11,'02_CLEAN_DATA'!$R$2:$R$570,1) -> 40 | D11: =COUNTIFS('02_CLEAN_DATA'!$L$2:$L$570,A11,'02_CLEAN_DATA'!$W$2:$W$570,"Met") -> 39 | E11: =COUNTIFS('02_CLEAN_DATA'!$L$2:$L$570,A11,'02_CLEAN_DATA'!$W$2:$W$570,"Missed") -> 1 | F11: =IF(C11=0,"",D11/C11) -> 0.975 | G11: =IF(OR($B$1="",F11=""),"",F11-$B$1) | H11: =COUNTIFS('02_CLEAN_DATA'!$L$2:$L$570,A11,'02_CLEAN_DATA'!$S$2:$S$570,"Customer Contracted Reasons") -> 40 | I11: =IF(B11=0,"",H11/B11) -> 1 | J11: =IFERROR(AVERAGEIF('02_CLEAN_DATA'!$L$2:$L$570,A11,'02_CLEAN_DATA'!$O$2:$O$570),"") -> 15.99125 | K11: {=IFERROR(MEDIAN(IF('02_CLEAN_DATA'!$L$2:$L$570=A11,'02_CLEAN_DATA'!$O$2:$O$570)),"")} -> 6.84
A12: 2026-05 | B12: =COUNTIF('02_CLEAN_DATA'!$L$2:$L$570,A12) -> 38 | C12: =COUNTIFS('02_CLEAN_DATA'!$L$2:$L$570,A12,'02_CLEAN_DATA'!$R$2:$R$570,1) -> 35 | D12: =COUNTIFS('02_CLEAN_DATA'!$L$2:$L$570,A12,'02_CLEAN_DATA'!$W$2:$W$570,"Met") -> 30 | E12: =COUNTIFS('02_CLEAN_DATA'!$L$2:$L$570,A12,'02_CLEAN_DATA'!$W$2:$W$570,"Missed") -> 5 | F12: =IF(C12=0,"",D12/C12) -> 0.85714286 | G12: =IF(OR($B$1="",F12=""),"",F12-$B$1) | H12: =COUNTIFS('02_CLEAN_DATA'!$L$2:$L$570,A12,'02_CLEAN_DATA'!$S$2:$S$570,"Customer Contracted Reasons") -> 38 | I12: =IF(B12=0,"",H12/B12) -> 1 | J12: =IFERROR(AVERAGEIF('02_CLEAN_DATA'!$L$2:$L$570,A12,'02_CLEAN_DATA'!$O$2:$O$570),"") -> 20.961053 | K12: {=IFERROR(MEDIAN(IF('02_CLEAN_DATA'!$L$2:$L$570=A12,'02_CLEAN_DATA'!$O$2:$O$570)),"")} -> 14.525
A13: 2026-06 | B13: =COUNTIF('02_CLEAN_DATA'!$L$2:$L$570,A13) -> 42 | C13: =COUNTIFS('02_CLEAN_DATA'!$L$2:$L$570,A13,'02_CLEAN_DATA'!$R$2:$R$570,1) -> 30 | D13: =COUNTIFS('02_CLEAN_DATA'!$L$2:$L$570,A13,'02_CLEAN_DATA'!$W$2:$W$570,"Met") -> 18 | E13: =COUNTIFS('02_CLEAN_DATA'!$L$2:$L$570,A13,'02_CLEAN_DATA'!$W$2:$W$570,"Missed") -> 12 | F13: =IF(C13=0,"",D13/C13) -> 0.6 | G13: =IF(OR($B$1="",F13=""),"",F13-$B$1) | H13: =COUNTIFS('02_CLEAN_DATA'!$L$2:$L$570,A13,'02_CLEAN_DATA'!$S$2:$S$570,"Customer Contracted Reasons") -> 42 | I13: =IF(B13=0,"",H13/B13) -> 1 | J13: =IFERROR(AVERAGEIF('02_CLEAN_DATA'!$L$2:$L$570,A13,'02_CLEAN_DATA'!$O$2:$O$570),"") -> 30.885952 | K13: {=IFERROR(MEDIAN(IF('02_CLEAN_DATA'!$L$2:$L$570=A13,'02_CLEAN_DATA'!$O$2:$O$570)),"")} -> 20.125
A14: 2026-07 | B14: =COUNTIF('02_CLEAN_DATA'!$L$2:$L$570,A14) -> 43 | C14: =COUNTIFS('02_CLEAN_DATA'!$L$2:$L$570,A14,'02_CLEAN_DATA'!$R$2:$R$570,1) -> 29 | D14: =COUNTIFS('02_CLEAN_DATA'!$L$2:$L$570,A14,'02_CLEAN_DATA'!$W$2:$W$570,"Met") -> 19 | E14: =COUNTIFS('02_CLEAN_DATA'!$L$2:$L$570,A14,'02_CLEAN_DATA'!$W$2:$W$570,"Missed") -> 10 | F14: =IF(C14=0,"",D14/C14) -> 0.65517241 | G14: =IF(OR($B$1="",F14=""),"",F14-$B$1) | H14: =COUNTIFS('02_CLEAN_DATA'!$L$2:$L$570,A14,'02_CLEAN_DATA'!$S$2:$S$570,"Customer Contracted Reasons") -> 43 | I14: =IF(B14=0,"",H14/B14) -> 1 | J14: =IFERROR(AVERAGEIF('02_CLEAN_DATA'!$L$2:$L$570,A14,'02_CLEAN_DATA'!$O$2:$O$570),"") -> 30.18186 | K14: {=IFERROR(MEDIAN(IF('02_CLEAN_DATA'!$L$2:$L$570=A14,'02_CLEAN_DATA'!$O$2:$O$570)),"")} -> 16.55
A15: 2026-08 | B15: =COUNTIF('02_CLEAN_DATA'!$L$2:$L$570,A15) -> 16 | C15: =COUNTIFS('02_CLEAN_DATA'!$L$2:$L$570,A15,'02_CLEAN_DATA'!$R$2:$R$570,1) -> 11 | D15: =COUNTIFS('02_CLEAN_DATA'!$L$2:$L$570,A15,'02_CLEAN_DATA'!$W$2:$W$570,"Met") -> 11 | E15: =COUNTIFS('02_CLEAN_DATA'!$L$2:$L$570,A15,'02_CLEAN_DATA'!$W$2:$W$570,"Missed") -> 0 | F15: =IF(C15=0,"",D15/C15) -> 1 | G15: =IF(OR($B$1="",F15=""),"",F15-$B$1) | H15: =COUNTIFS('02_CLEAN_DATA'!$L$2:$L$570,A15,'02_CLEAN_DATA'!$S$2:$S$570,"Customer Contracted Reasons") -> 13 | I15: =IF(B15=0,"",H15/B15) -> 0.8125 | J15: =IFERROR(AVERAGEIF('02_CLEAN_DATA'!$L$2:$L$570,A15,'02_CLEAN_DATA'!$O$2:$O$570),"") -> 9.990625 | K15: {=IFERROR(MEDIAN(IF('02_CLEAN_DATA'!$L$2:$L$570=A15,'02_CLEAN_DATA'!$O$2:$O$570)),"")} -> 5.61
A16: YTD TOTAL | B16: =SUM(B3:B15) -> 568 | C16: =SUM(C3:C15) -> 435 | D16: =SUM(D3:D15) -> 337 | E16: =SUM(E3:E15) -> 98 | F16: =IF(C16=0,"",D16/C16) -> 0.77471264 | G16: =IF(OR($B$1="",F16=""),"",F16-$B$1) | H16: =SUM(H3:H15) -> 353 | I16: =IF(B16=0,"",H16/B16) -> 0.62147887 | J16: {=AVERAGE('02_CLEAN_DATA'!$O$2:$O$570)} -> 30.227606 | K16: {=MEDIAN('02_CLEAN_DATA'!$O$2:$O$570)} -> 14.04
A18: SLA % = Final SLA Met ÷ SLA Eligible tickets for the month (Adjusted / Opportunity basis — see 00_README). Enter a contracted target in B1 to populate the variance column and the reference elsewhere in this workbook. Monthly ticket totals sum to 568 of 569 YTD tickets — the one open (unclosed) ticket has no Closed Date and is therefore not bucketed into any month; it is still counted in the workbook-wide Total Tickets KPI.

Sheet 05_EXCEPTIONS_MITIGATIONS
A1: Exception / Mitigation Analysis — Column CJ (Mitigation Reason Description)
A3: Overall Distribution (All Tickets)
A4: Category | B4: Ticket Count | C4: % of All Tickets
A5: Customer Contracted Reasons | B5: =COUNTIF('02_CLEAN_DATA'!$S$2:$S$570,"Customer Contracted Reasons") -> 353 | C5: =B5/COUNTA('02_CLEAN_DATA'!$S$2:$S$570) -> 0.62038664
A6: No Exception | B6: =COUNTIF('02_CLEAN_DATA'!$S$2:$S$570,"No Exception") -> 216 | C6: =B6/COUNTA('02_CLEAN_DATA'!$S$2:$S$570) -> 0.37961336
A7: TOTAL | B7: =SUM(B5:B6) -> 569 | C7: =SUM(C5:C6) -> 1
A9: SLA Performance: Exception-Tagged vs No-Exception Tickets (SLA-Eligible Population Only)
A10: Category | B10: SLA Eligible | C10: SLA Met | D10: SLA Missed | E10: SLA % | F10: Avg Resolution (Hrs)
A11: Customer Contracted Reasons | B11: =COUNTIFS('02_CLEAN_DATA'!$S$2:$S$570,"Customer Contracted Reasons",'02_CLEAN_DATA'!$R$2:$R$570,1) -> 288 | C11: =COUNTIFS('02_CLEAN_DATA'!$S$2:$S$570,"Customer Contracted Reasons",'02_CLEAN_DATA'!$W$2:$W$570,"Met") -> 224 | D11: =COUNTIFS('02_CLEAN_DATA'!$S$2:$S$570,"Customer Contracted Reasons",'02_CLEAN_DATA'!$W$2:$W$570,"Missed") -> 64 | E11: =IF(B11=0,"",C11/B11) -> 0.77777778 | F11: {=IFERROR(AVERAGE(IF('02_CLEAN_DATA'!$S$2:$S$570="Customer Contracted Reasons",'02_CLEAN_DATA'!$O$2:$O$570)),"")} -> 32.344476
A12: No Exception | B12: =COUNTIFS('02_CLEAN_DATA'!$S$2:$S$570,"No Exception",'02_CLEAN_DATA'!$R$2:$R$570,1) -> 147 | C12: =COUNTIFS('02_CLEAN_DATA'!$S$2:$S$570,"No Exception",'02_CLEAN_DATA'!$W$2:$W$570,"Met") -> 113 | D12: =COUNTIFS('02_CLEAN_DATA'!$S$2:$S$570,"No Exception",'02_CLEAN_DATA'!$W$2:$W$570,"Missed") -> 34 | E12: =IF(B12=0,"",C12/B12) -> 0.76870748 | F12: {=IFERROR(AVERAGE(IF('02_CLEAN_DATA'!$S$2:$S$570="No Exception",'02_CLEAN_DATA'!$O$2:$O$570)),"")} -> 26.628148
A14: Interpretation note: this compares outcomes for tickets carrying a 'Customer Contracted Reasons' mitigation against tickets with none. It shows association, not causation — a mitigation reason describes why a ticket was reviewed for adjustment, not a guarantee that it changed the SLA outcome. See 00_README for exact logic.
A21: Monthly Exception Trend
A22: Month | B22: Total Tickets | C22: Exceptions (CCR) | D22: Exception Rate
A23: 2025-08 | B23: =COUNTIF('02_CLEAN_DATA'!$L$2:$L$570,A23) -> 39 | C23: =COUNTIFS('02_CLEAN_DATA'!$L$2:$L$570,A23,'02_CLEAN_DATA'!$S$2:$S$570,"Customer Contracted Reasons") -> 3 | D23: =IF(B23=0,"",C23/B23) -> 0.076923077
A24: 2025-09 | B24: =COUNTIF('02_CLEAN_DATA'!$L$2:$L$570,A24) -> 57 | C24: =COUNTIFS('02_CLEAN_DATA'!$L$2:$L$570,A24,'02_CLEAN_DATA'!$S$2:$S$570,"Customer Contracted Reasons") -> 11 | D24: =IF(B24=0,"",C24/B24) -> 0.19298246
A25: 2025-10 | B25: =COUNTIF('02_CLEAN_DATA'!$L$2:$L$570,A25) -> 56 | C25: =COUNTIFS('02_CLEAN_DATA'!$L$2:$L$570,A25,'02_CLEAN_DATA'!$S$2:$S$570,"Customer Contracted Reasons") -> 7 | D25: =IF(B25=0,"",C25/B25) -> 0.125
A26: 2025-11 | B26: =COUNTIF('02_CLEAN_DATA'!$L$2:$L$570,A26) -> 44 | C26: =COUNTIFS('02_CLEAN_DATA'!$L$2:$L$570,A26,'02_CLEAN_DATA'!$S$2:$S$570,"Customer Contracted Reasons") -> 5 | D26: =IF(B26=0,"",C26/B26) -> 0.11363636
A27: 2025-12 | B27: =COUNTIF('02_CLEAN_DATA'!$L$2:$L$570,A27) -> 50 | C27: =COUNTIFS('02_CLEAN_DATA'!$L$2:$L$570,A27,'02_CLEAN_DATA'!$S$2:$S$570,"Customer Contracted Reasons") -> 8 | D27: =IF(B27=0,"",C27/B27) -> 0.16
A28: 2026-01 | B28: =COUNTIF('02_CLEAN_DATA'!$L$2:$L$570,A28) -> 57 | C28: =COUNTIFS('02_CLEAN_DATA'!$L$2:$L$570,A28,'02_CLEAN_DATA'!$S$2:$S$570,"Customer Contracted Reasons") -> 57 | D28: =IF(B28=0,"",C28/B28) -> 1
A29: 2026-02 | B29: =COUNTIF('02_CLEAN_DATA'!$L$2:$L$570,A29) -> 41 | C29: =COUNTIFS('02_CLEAN_DATA'!$L$2:$L$570,A29,'02_CLEAN_DATA'!$S$2:$S$570,"Customer Contracted Reasons") -> 41 | D29: =IF(B29=0,"",C29/B29) -> 1
A30: 2026-03 | B30: =COUNTIF('02_CLEAN_DATA'!$L$2:$L$570,A30) -> 45 | C30: =COUNTIFS('02_CLEAN_DATA'!$L$2:$L$570,A30,'02_CLEAN_DATA'!$S$2:$S$570,"Customer Contracted Reasons") -> 45 | D30: =IF(B30=0,"",C30/B30) -> 1
A31: 2026-04 | B31: =COUNTIF('02_CLEAN_DATA'!$L$2:$L$570,A31) -> 40 | C31: =COUNTIFS('02_CLEAN_DATA'!$L$2:$L$570,A31,'02_CLEAN_DATA'!$S$2:$S$570,"Customer Contracted Reasons") -> 40 | D31: =IF(B31=0,"",C31/B31) -> 1
A32: 2026-05 | B32: =COUNTIF('02_CLEAN_DATA'!$L$2:$L$570,A32) -> 38 | C32: =COUNTIFS('02_CLEAN_DATA'!$L$2:$L$570,A32,'02_CLEAN_DATA'!$S$2:$S$570,"Customer Contracted Reasons") -> 38 | D32: =IF(B32=0,"",C32/B32) -> 1
A33: 2026-06 | B33: =COUNTIF('02_CLEAN_DATA'!$L$2:$L$570,A33) -> 42 | C33: =COUNTIFS('02_CLEAN_DATA'!$L$2:$L$570,A33,'02_CLEAN_DATA'!$S$2:$S$570,"Customer Contracted Reasons") -> 42 | D33: =IF(B33=0,"",C33/B33) -> 1
A34: 2026-07 | B34: =COUNTIF('02_CLEAN_DATA'!$L$2:$L$570,A34) -> 43 | C34: =COUNTIFS('02_CLEAN_DATA'!$L$2:$L$570,A34,'02_CLEAN_DATA'!$S$2:$S$570,"Customer Contracted Reasons") -> 43 | D34: =IF(B34=0,"",C34/B34) -> 1
A35: 2026-08 | B35: =COUNTIF('02_CLEAN_DATA'!$L$2:$L$570,A35) -> 16 | C35: =COUNTIFS('02_CLEAN_DATA'!$L$2:$L$570,A35,'02_CLEAN_DATA'!$S$2:$S$570,"Customer Contracted Reasons") -> 13 | D35: =IF(B35=0,"",C35/B35) -> 0.8125
A37: Key observation: the 'Customer Contracted Reasons' exception rate rose sharply starting January 2026 — from roughly 10-20% of monthly tickets in Aug-Dec 2025 to effectively 100% of tickets every month from Jan 2026 through Jul 2026. This coincides with the Mitigated Indicator field showing fully-processed mitigations (value 2) appearing for the first time in Jan 2026 (0 occurrences before). This is a material change in how exceptions are being applied and is recommended for review with the service vendor.

Sheet 06_STORE_ANALYSIS
A1: Store # | B1: Store Name | C1: City | D1: State | E1: Total Tickets | F1: SLA Eligible | G1: SLA Met | H1: SLA Missed | I1: SLA % | J1: Exceptions (CCR) | K1: Exception Rate | L1: Avg Resolution (Hrs) | M1: Median Resolution (Hrs) | N1: Rank Key (Avg Res, 5+ tickets) | O1: Rank Key (SLA %, 5+ tickets) | P1: Rank Key (Missed Count) | Q1: Rank Key (Below-Target, 10+ tickets)
A2: 448 | B2: Fresh Thyme #448 | C2: St. Louis | D2: MO | E2: =COUNTIF('02_CLEAN_DATA'!$B$2:$B$570,A2) -> 8 | F2: =COUNTIFS('02_CLEAN_DATA'!$B$2:$B$570,A2,'02_CLEAN_DATA'!$R$2:$R$570,1) -> 4 | G2: =COUNTIFS('02_CLEAN_DATA'!$B$2:$B$570,A2,'02_CLEAN_DATA'!$W$2:$W$570,"Met") -> 3 | H2: =COUNTIFS('02_CLEAN_DATA'!$B$2:$B$570,A2,'02_CLEAN_DATA'!$W$2:$W$570,"Missed") -> 1 | I2: =IF(F2=0,"",G2/F2) -> 0.75 | J2: =COUNTIFS('02_CLEAN_DATA'!$B$2:$B$570,A2,'02_CLEAN_DATA'!$S$2:$S$570,"Customer Contracted Reasons") -> 3 | K2: =IF(E2=0,"",J2/E2) -> 0.375 | L2: =IFERROR(AVERAGEIF('02_CLEAN_DATA'!$B$2:$B$570,A2,'02_CLEAN_DATA'!$O$2:$O$570),"") -> 13.93875 | M2: {=IFERROR(MEDIAN(IF('02_CLEAN_DATA'!$B$2:$B$570=A2,'02_CLEAN_DATA'!$O$2:$O$570)),"")} -> 8.35 | N2: =IF(E2>=5,L2+ROW()/10000000,"") -> 13.93875 | O2: =IF(E2>=5,I2+ROW()/10000000,"") -> 0.7500002 | P2: =H2+ROW()/10000000 -> 1.0000002 | Q2: =IF(AND(E2>=10,I2<>""),(1-I2)+ROW()/10000000,"")
A3: 491 | B3: Fresh Thyme #491 | C3: Kirkwood | D3: MO | E3: =COUNTIF('02_CLEAN_DATA'!$B$2:$B$570,A3) -> 4 | F3: =COUNTIFS('02_CLEAN_DATA'!$B$2:$B$570,A3,'02_CLEAN_DATA'!$R$2:$R$570,1) -> 1 | G3: =COUNTIFS('02_CLEAN_DATA'!$B$2:$B$570,A3,'02_CLEAN_DATA'!$W$2:$W$570,"Met") -> 1 | H3: =COUNTIFS('02_CLEAN_DATA'!$B$2:$B$570,A3,'02_CLEAN_DATA'!$W$2:$W$570,"Missed") -> 0 | I3: =IF(F3=0,"",G3/F3) -> 1 | J3: =COUNTIFS('02_CLEAN_DATA'!$B$2:$B$570,A3,'02_CLEAN_DATA'!$S$2:$S$570,"Customer Contracted Reasons") -> 0 | K3: =IF(E3=0,"",J3/E3) -> 0 | L3: =IFERROR(AVERAGEIF('02_CLEAN_DATA'!$B$2:$B$570,A3,'02_CLEAN_DATA'!$O$2:$O$570),"") -> 27.7375 | M3: {=IFERROR(MEDIAN(IF('02_CLEAN_DATA'!$B$2:$B$570=A3,'02_CLEAN_DATA'!$O$2:$O$570)),"")} -> 11.1 | N3: =IF(E3>=5,L3+ROW()/10000000,"") | O3: =IF(E3>=5,I3+ROW()/10000000,"") | P3: =H3+ROW()/10000000 -> 3e-07 | Q3: =IF(AND(E3>=10,I3<>""),(1-I3)+ROW()/10000000,"")
A4: 492 | B4: Fresh Thyme #492 | C4: Ballwin | D4: MO | E4: =COUNTIF('02_CLEAN_DATA'!$B$2:$B$570,A4) -> 4 | F4: =COUNTIFS('02_CLEAN_DATA'!$B$2:$B$570,A4,'02_CLEAN_DATA'!$R$2:$R$570,1) -> 1 | G4: =COUNTIFS('02_CLEAN_DATA'!$B$2:$B$570,A4,'02_CLEAN_DATA'!$W$2:$W$570,"Met") -> 1 | H4: =COUNTIFS('02_CLEAN_DATA'!$B$2:$B$570,A4,'02_CLEAN_DATA'!$W$2:$W$570,"Missed") -> 0 | I4: =IF(F4=0,"",G4/F4) -> 1 | J4: =COUNTIFS('02_CLEAN_DATA'!$B$2:$B$570,A4,'02_CLEAN_DATA'!$S$2:$S$570,"Customer Contracted Reasons") -> 2 | K4: =IF(E4=0,"",J4/E4) -> 0.5 | L4: =IFERROR(AVERAGEIF('02_CLEAN_DATA'!$B$2:$B$570,A4,'02_CLEAN_DATA'!$O$2:$O$570),"") -> 4.5075 | M4: {=IFERROR(MEDIAN(IF('02_CLEAN_DATA'!$B$2:$B$570=A4,'02_CLEAN_DATA'!$O$2:$O$570)),"")} -> 4.6 | N4: =IF(E4>=5,L4+ROW()/10000000,"") | O4: =IF(E4>=5,I4+ROW()/10000000,"") | P4: =H4+ROW()/10000000 -> 4e-07 | Q4: =IF(AND(E4>=10,I4<>""),(1-I4)+ROW()/10000000,"")
A5: 493 | B5: Fresh Thyme #493 | C5: O Fallon | D5: MO | E5: =COUNTIF('02_CLEAN_DATA'!$B$2:$B$570,A5) -> 20 | F5: =COUNTIFS('02_CLEAN_DATA'!$B$2:$B$570,A5,'02_CLEAN_DATA'!$R$2:$R$570,1) -> 11 | G5: =COUNTIFS('02_CLEAN_DATA'!$B$2:$B$570,A5,'02_CLEAN_DATA'!$W$2:$W$570,"Met") -> 9 | H5: =COUNTIFS('02_CLEAN_DATA'!$B$2:$B$570,A5,'02_CLEAN_DATA'!$W$2:$W$570,"Missed") -> 2 | I5: =IF(F5=0,"",G5/F5) -> 0.81818182 | J5: =COUNTIFS('02_CLEAN_DATA'!$B$2:$B$570,A5,'02_CLEAN_DATA'!$S$2:$S$570,"Customer Contracted Reasons") -> 13 | K5: =IF(E5=0,"",J5/E5) -> 0.65 | L5: =IFERROR(AVERAGEIF('02_CLEAN_DATA'!$B$2:$B$570,A5,'02_CLEAN_DATA'!$O$2:$O$570),"") -> 15.991 | M5: {=IFERROR(MEDIAN(IF('02_CLEAN_DATA'!$B$2:$B$570=A5,'02_CLEAN_DATA'!$O$2:$O$570)),"")} -> 15.475 | N5: =IF(E5>=5,L5+ROW()/10000000,"") -> 15.991001 | O5: =IF(E5>=5,I5+ROW()/10000000,"") -> 0.81818232 | P5: =H5+ROW()/10000000 -> 2.0000005 | Q5: =IF(AND(E5>=10,I5<>""),(1-I5)+ROW()/10000000,"") -> 0.18181868
A6: 494 | B6: Fresh Thyme #494 | C6: Saint Louis | D6: MO | E6: =COUNTIF('02_CLEAN_DATA'!$B$2:$B$570,A6) -> 13 | F6: =COUNTIFS('02_CLEAN_DATA'!$B$2:$B$570,A6,'02_CLEAN_DATA'!$R$2:$R$570,1) -> 10 | G6: =COUNTIFS('02_CLEAN_DATA'!$B$2:$B$570,A6,'02_CLEAN_DATA'!$W$2:$W$570,"Met") -> 10 | H6: =COUNTIFS('02_CLEAN_DATA'!$B$2:$B$570,A6,'02_CLEAN_DATA'!$W$2:$W$570,"Missed") -> 0 | I6: =IF(F6=0,"",G6/F6) -> 1 | J6: =COUNTIFS('02_CLEAN_DATA'!$B$2:$B$570,A6,'02_CLEAN_DATA'!$S$2:$S$570,"Customer Contracted Reasons") -> 6 | K6: =IF(E6=0,"",J6/E6) -> 0.46153846 | L6: =IFERROR(AVERAGEIF('02_CLEAN_DATA'!$B$2:$B$570,A6,'02_CLEAN_DATA'!$O$2:$O$570),"") -> 15.615385 | M6: {=IFERROR(MEDIAN(IF('02_CLEAN_DATA'!$B$2:$B$570=A6,'02_CLEAN_DATA'!$O$2:$O$570)),"")} -> 7.68 | N6: =IF(E6>=5,L6+ROW()/10000000,"") -> 15.615385 | O6: =IF(E6>=5,I6+ROW()/10000000,"") -> 1.0000006 | P6: =H6+ROW()/10000000 -> 6e-07 | Q6: =IF(AND(E6>=10,I6<>""),(1-I6)+ROW()/10000000,"") -> 6e-07
A7: 495 | B7: Fresh Thyme #495 | C7: Saint Peters | D7: MO | E7: =COUNTIF('02_CLEAN_DATA'!$B$2:$B$570,A7) -> 11 | F7: =COUNTIFS('02_CLEAN_DATA'!$B$2:$B$570,A7,'02_CLEAN_DATA'!$R$2:$R$570,1) -> 7 | G7: =COUNTIFS('02_CLEAN_DATA'!$B$2:$B$570,A7,'02_CLEAN_DATA'!$W$2:$W$570,"Met") -> 6 | H7: =COUNTIFS('02_CLEAN_DATA'!$B$2:$B$570,A7,'02_CLEAN_DATA'!$W$2:$W$570,"Missed") -> 1 | I7: =IF(F7=0,"",G7/F7) -> 0.85714286 | J7: =COUNTIFS('02_CLEAN_DATA'!$B$2:$B$570,A7,'02_CLEAN_DATA'!$S$2:$S$570,"Customer Contracted Reasons") -> 5 | K7: =IF(E7=0,"",J7/E7) -> 0.45454545 | L7: =IFERROR(AVERAGEIF('02_CLEAN_DATA'!$B$2:$B$570,A7,'02_CLEAN_DATA'!$O$2:$O$570),"") -> 16.460909 | M7: {=IFERROR(MEDIAN(IF('02_CLEAN_DATA'!$B$2:$B$570=A7,'02_CLEAN_DATA'!$O$2:$O$570)),"")} -> 4.25 | N7: =IF(E7>=5,L7+ROW()/10000000,"") -> 16.46091 | O7: =IF(E7>=5,I7+ROW()/10000000,"") -> 0.85714356 | P7: =H7+ROW()/10000000 -> 1.0000007 | Q7: =IF(AND(E7>=10,I7<>""),(1-I7)+ROW()/10000000,"") -> 0.14285784
A8: 496 | B8: Fresh Thyme #496 | C8: Bridgeville | D8: PA | E8: =COUNTIF('02_CLEAN_DATA'!$B$2:$B$570,A8) -> 6 | F8: =COUNTIFS('02_CLEAN_DATA'!$B$2:$B$570,A8,'02_CLEAN_DATA'!$R$2:$R$570,1) -> 6 | G8: =COUNTIFS('02_CLEAN_DATA'!$B$2:$B$570,A8,'02_CLEAN_DATA'!$W$2:$W$570,"Met") -> 6 | H8: =COUNTIFS('02_CLEAN_DATA'!$B$2:$B$570,A8,'02_CLEAN_DATA'!$W$2:$W$570,"Missed") -> 0 | I8: =IF(F8=0,"",G8/F8) -> 1 | J8: =COUNTIFS('02_CLEAN_DATA'!$B$2:$B$570,A8,'02_CLEAN_DATA'!$S$2:$S$570,"Customer Contracted Reasons") -> 5 | K8: =IF(E8=0,"",J8/E8) -> 0.83333333 | L8: =IFERROR(AVERAGEIF('02_CLEAN_DATA'!$B$2:$B$570,A8,'02_CLEAN_DATA'!$O$2:$O$570),"") -> 15.541667 | M8: {=IFERROR(MEDIAN(IF('02_CLEAN_DATA'!$B$2:$B$570=A8,'02_CLEAN_DATA'!$O$2:$O$570)),"")} -> 13.14 | N8: =IF(E8>=5,L8+ROW()/10000000,"") -> 15.541667 | O8: =IF(E8>=5,I8+ROW()/10000000,"") -> 1.0000008 | P8: =H8+ROW()/10000000 -> 8e-07 | Q8: =IF(AND(E8>=10,I8<>""),(1-I8)+ROW()/10000000,"")
A9: 497 | B9: Fresh Thyme #497 | C9: Pleasant Hills | D9: PA | E9: =COUNTIF('02_CLEAN_DATA'!$B$2:$B$570,A9) -> 9 | F9: =COUNTIFS('02_CLEAN_DATA'!$B$2:$B$570,A9,'02_CLEAN_DATA'!$R$2:$R$570,1) -> 7 | G9: =COUNTIFS('02_CLEAN_DATA'!$B$2:$B$570,A9,'02_CLEAN_DATA'!$W$2:$W$570,"Met") -> 7 | H9: =COUNTIFS('02_CLEAN_DATA'!$B$2:$B$570,A9,'02_CLEAN_DATA'!$W$2:$W$570,"Missed") -> 0 | I9: =IF(F9=0,"",G9/F9) -> 1 | J9: =COUNTIFS('02_CLEAN_DATA'!$B$2:$B$570,A9,'02_CLEAN_DATA'!$S$2:$S$570,"Customer Contracted Reasons") -> 6 | K9: =IF(E9=0,"",J9/E9) -> 0.66666667 | L9: =IFERROR(AVERAGEIF('02_CLEAN_DATA'!$B$2:$B$570,A9,'02_CLEAN_DATA'!$O$2:$O$570),"") -> 20.321111 | M9: {=IFERROR(MEDIAN(IF('02_CLEAN_DATA'!$B$2:$B$570=A9,'02_CLEAN_DATA'!$O$2:$O$570)),"")} -> 14.87 | N9: =IF(E9>=5,L9+ROW()/10000000,"") -> 20.321112 | O9: =IF(E9>=5,I9+ROW()/10000000,"") -> 1.0000009 | P9: =H9+ROW()/10000000 -> 9e-07 | Q9: =IF(AND(E9>=10,I9<>""),(1-I9)+ROW()/10000000,"")
A10: 498 | B10: Fresh Thyme #498 | C10: Cranberry Township | D10: PA | E10: =COUNTIF('02_CLEAN_DATA'!$B$2:$B$570,A10) -> 2 | F10: =COUNTIFS('02_CLEAN_DATA'!$B$2:$B$570,A10,'02_CLEAN_DATA'!$R$2:$R$570,1) -> 2 | G10: =COUNTIFS('02_CLEAN_DATA'!$B$2:$B$570,A10,'02_CLEAN_DATA'!$W$2:$W$570,"Met") -> 1 | H10: =COUNTIFS('02_CLEAN_DATA'!$B$2:$B$570,A10,'02_CLEAN_DATA'!$W$2:$W$570,"Missed") -> 1 | I10: =IF(F10=0,"",G10/F10) -> 0.5 | J10: =COUNTIFS('02_CLEAN_DATA'!$B$2:$B$570,A10,'02_CLEAN_DATA'!$S$2:$S$570,"Customer Contracted Reasons") -> 2 | K10: =IF(E10=0,"",J10/E10) -> 1 | L10: =IFERROR(AVERAGEIF('02_CLEAN_DATA'!$B$2:$B$570,A10,'02_CLEAN_DATA'!$O$2:$O$570),"") -> 26.31 | M10: {=IFERROR(MEDIAN(IF('02_CLEAN_DATA'!$B$2:$B$570=A10,'02_CLEAN_DATA'!$O$2:$O$570)),"")} -> 26.31 | N10: =IF(E10>=5,L10+ROW()/10000000,"") | O10: =IF(E10>=5,I10+ROW()/10000000,"") | P10: =H10+ROW()/10000000 -> 1.000001 | Q10: =IF(AND(E10>=10,I10<>""),(1-I10)+ROW()/10000000,"")
A11: 499 | B11: Fresh Thyme #499 | C11: Newport | D11: KY | E11: =COUNTIF('02_CLEAN_DATA'!$B$2:$B$570,A11) -> 1 | F11: =COUNTIFS('02_CLEAN_DATA'!$B$2:$B$570,A11,'02_CLEAN_DATA'!$R$2:$R$570,1) -> 1 | G11: =COUNTIFS('02_CLEAN_DATA'!$B$2:$B$570,A11,'02_CLEAN_DATA'!$W$2:$W$570,"Met") -> 1 | H11: =COUNTIFS('02_CLEAN_DATA'!$B$2:$B$570,A11,'02_CLEAN_DATA'!$W$2:$W$570,"Missed") -> 0 | I11: =IF(F11=0,"",G11/F11) -> 1 | J11: =COUNTIFS('02_CLEAN_DATA'!$B$2:$B$570,A11,'02_CLEAN_DATA'!$S$2:$S$570,"Customer Contracted Reasons") -> 0 | K11: =IF(E11=0,"",J11/E11) -> 0 | L11: =IFERROR(AVERAGEIF('02_CLEAN_DATA'!$B$2:$B$570,A11,'02_CLEAN_DATA'!$O$2:$O$570),"") -> 10.87 | M11: {=IFERROR(MEDIAN(IF('02_CLEAN_DATA'!$B$2:$B$570=A11,'02_CLEAN_DATA'!$O$2:$O$570)),"")} -> 10.87 | N11: =IF(E11>=5,L11+ROW()/10000000,"") | O11: =IF(E11>=5,I11+ROW()/10000000,"") | P11: =H11+ROW()/10000000 -> 1.1e-06 | Q11: =IF(AND(E11>=10,I11<>""),(1-I11)+ROW()/10000000,"")
A12: 522 | B12: Fresh Thyme #522 | C12: Indianapolis | D12: IN | E12: =COUNTIF('02_CLEAN_DATA'!$B$2:$B$570,A12) -> 13 | F12: =COUNTIFS('02_CLEAN_DATA'!$B$2:$B$570,A12,'02_CLEAN_DATA'!$R$2:$R$570,1) -> 12 | G12: =COUNTIFS('02_CLEAN_DATA'!$B$2:$B$570,A12,'02_CLEAN_DATA'!$W$2:$W$570,"Met") -> 7 | H12: =COUNTIFS('02_CLEAN_DATA'!$B$2:$B$570,A12,'02_CLEAN_DATA'!$W$2:$W$570,"Missed") -> 5 | I12: =IF(F12=0,"",G12/F12) -> 0.58333333 | J12: =COUNTIFS('02_CLEAN_DATA'!$B$2:$B$570,A12,'02_CLEAN_DATA'!$S$2:$S$570,"Customer Contracted Reasons") -> 13 | K12: =IF(E12=0,"",J12/E12) -> 1 | L12: =IFERROR(AVERAGEIF('02_CLEAN_DATA'!$B$2:$B$570,A12,'02_CLEAN_DATA'!$O$2:$O$570),"") -> 72.347692 | M12: {=IFERROR(MEDIAN(IF('02_CLEAN_DATA'!$B$2:$B$570=A12,'02_CLEAN_DATA'!$O$2:$O$570)),"")} -> 32.1 | N12: =IF(E12>=5,L12+ROW()/10000000,"") -> 72.347694 | O12: =IF(E12>=5,I12+ROW()/10000000,"") -> 0.58333453 | P12: =H12+ROW()/10000000 -> 5.0000012 | Q12: =IF(AND(E12>=10,I12<>""),(1-I12)+ROW()/10000000,"") -> 0.41666787
A13: 523 | B13: Fresh Thyme #523 | C13: Lafayette | D13: IN | E13: =COUNTIF('02_CLEAN_DATA'!$B$2:$B$570,A13) -> 7 | F13: =COUNTIFS('02_CLEAN_DATA'!$B$2:$B$570,A13,'02_CLEAN_DATA'!$R$2:$R$570,1) -> 7 | G13: =COUNTIFS('02_CLEAN_DATA'!$B$2:$B$570,A13,'02_CLEAN_DATA'!$W$2:$W$570,"Met") -> 5 | H13: =COUNTIFS('02_CLEAN_DATA'!$B$2:$B$570,A13,'02_CLEAN_DATA'!$W$2:$W$570,"Missed") -> 2 | I13: =IF(F13=0,"",G13/F13) -> 0.71428571 | J13: =COUNTIFS('02_CLEAN_DATA'!$B$2:$B$570,A13,'02_CLEAN_DATA'!$S$2:$S$570,"Customer Contracted Reasons") -> 4 | K13: =IF(E13=0,"",J13/E13) -> 0.57142857 | L13: =IFERROR(AVERAGEIF('02_CLEAN_DATA'!$B$2:$B$570,A13,'02_CLEAN_DATA'!$O$2:$O$570),"") -> 16.311429 | M13: {=IFERROR(MEDIAN(IF('02_CLEAN_DATA'!$B$2:$B$570=A13,'02_CLEAN_DATA'!$O$2:$O$570)),"")} -> 18.6 | N13: =IF(E13>=5,L13+ROW()/10000000,"") -> 16.31143 | O13: =IF(E13>=5,I13+ROW()/10000000,"") -> 0.71428701 | P13: =H13+ROW()/10000000 -> 2.0000013 | Q13: =IF(AND(E13>=10,I13<>""),(1-I13)+ROW()/10000000,"")
... A70: 968 | B70: Fresh Thyme #968 | C70: Davenport | D70: IA | E70: =COUNTIF('02_CLEAN_DATA'!$B$2:$B$570,A70) -> 6 | F70: =COUNTIFS('02_CLEAN_DATA'!$B$2:$B$570,A70,'02_CLEAN_DATA'!$R$2:$R$570,1) -> 4 | G70: =COUNTIFS('02_CLEAN_DATA'!$B$2:$B$570,A70,'02_CLEAN_DATA'!$W$2:$W$570,"Met") -> 4 | H70: =COUNTIFS('02_CLEAN_DATA'!$B$2:$B$570,A70,'02_CLEAN_DATA'!$W$2:$W$570,"Missed") -> 0 | I70: =IF(F70=0,"",G70/F70) -> 1 | J70: =COUNTIFS('02_CLEAN_DATA'!$B$2:$B$570,A70,'02_CLEAN_DATA'!$S$2:$S$570,"Customer Contracted Reasons") -> 4 | K70: =IF(E70=0,"",J70/E70) -> 0.66666667 | L70: =IFERROR(AVERAGEIF('02_CLEAN_DATA'!$B$2:$B$570,A70,'02_CLEAN_DATA'!$O$2:$O$570),"") -> 9.4383333 | M70: {=IFERROR(MEDIAN(IF('02_CLEAN_DATA'!$B$2:$B$570=A70,'02_CLEAN_DATA'!$O$2:$O$570)),"")} -> 4.55 | N70: =IF(E70>=5,L70+ROW()/10000000,"") -> 9.4383403 | O70: =IF(E70>=5,I70+ROW()/10000000,"") -> 1.000007 | P70: =H70+ROW()/10000000 -> 7e-06 | Q70: =IF(AND(E70>=10,I70<>""),(1-I70)+ROW()/10000000,"")
A73: Note: SLA % shown only for stores with SLA-eligible tickets (Opportunity Indicator = 1). Stores with very low ticket volume (<5) should be interpreted with caution — see 00_README. Columns N-Q are internal ranking helper columns used by 08_RESOLUTION_ANALYSIS and 09_ADVANCED_INSIGHTS; hidden from view.

Sheet 07_TECHNICIAN_ANALYSIS
A1: Tech Code | B1: Technician | C1: Total Tickets | D1: SLA Eligible | E1: SLA Met | F1: SLA Missed | G1: SLA % | H1: Exceptions (CCR) | I1: Avg Resolution (Hrs) | J1: Median Resolution (Hrs) | K1: Meets Min Threshold (5+) | L1: Rank Key (Avg Res, 5+ tickets) | M1: Rank Key (Missed Count)
A2: US153R72 | B2: Carlson Paul | C2: =COUNTIF('02_CLEAN_DATA'!$G$2:$G$570,A2) -> 21 | D2: =COUNTIFS('02_CLEAN_DATA'!$G$2:$G$570,A2,'02_CLEAN_DATA'!$R$2:$R$570,1) -> 14 | E2: =COUNTIFS('02_CLEAN_DATA'!$G$2:$G$570,A2,'02_CLEAN_DATA'!$W$2:$W$570,"Met") -> 9 | F2: =COUNTIFS('02_CLEAN_DATA'!$G$2:$G$570,A2,'02_CLEAN_DATA'!$W$2:$W$570,"Missed") -> 5 | G2: =IF(D2=0,"",E2/D2) -> 0.64285714 | H2: =COUNTIFS('02_CLEAN_DATA'!$G$2:$G$570,A2,'02_CLEAN_DATA'!$S$2:$S$570,"Customer Contracted Reasons") -> 8 | I2: =IFERROR(AVERAGEIF('02_CLEAN_DATA'!$G$2:$G$570,A2,'02_CLEAN_DATA'!$O$2:$O$570),"") -> 63.577619 | J2: {=IFERROR(MEDIAN(IF('02_CLEAN_DATA'!$G$2:$G$570=A2,'02_CLEAN_DATA'!$O$2:$O$570)),"")} -> 16.97 | K2: =IF(C2>=5,"Yes","No") -> Yes | L2: =IF(C2>=5,I2+ROW()/10000000,"") -> 63.577619 | M2: =F2+ROW()/10000000 -> 5.0000002
A3: US153C07 | B3: August Ronald | C3: =COUNTIF('02_CLEAN_DATA'!$G$2:$G$570,A3) -> 20 | D3: =COUNTIFS('02_CLEAN_DATA'!$G$2:$G$570,A3,'02_CLEAN_DATA'!$R$2:$R$570,1) -> 20 | E3: =COUNTIFS('02_CLEAN_DATA'!$G$2:$G$570,A3,'02_CLEAN_DATA'!$W$2:$W$570,"Met") -> 10 | F3: =COUNTIFS('02_CLEAN_DATA'!$G$2:$G$570,A3,'02_CLEAN_DATA'!$W$2:$W$570,"Missed") -> 10 | G3: =IF(D3=0,"",E3/D3) -> 0.5 | H3: =COUNTIFS('02_CLEAN_DATA'!$G$2:$G$570,A3,'02_CLEAN_DATA'!$S$2:$S$570,"Customer Contracted Reasons") -> 18 | I3: =IFERROR(AVERAGEIF('02_CLEAN_DATA'!$G$2:$G$570,A3,'02_CLEAN_DATA'!$O$2:$O$570),"") -> 29.4275 | J3: {=IFERROR(MEDIAN(IF('02_CLEAN_DATA'!$G$2:$G$570=A3,'02_CLEAN_DATA'!$O$2:$O$570)),"")} -> 24.55 | K3: =IF(C3>=5,"Yes","No") -> Yes | L3: =IF(C3>=5,I3+ROW()/10000000,"") -> 29.4275 | M3: =F3+ROW()/10000000 -> 10
A4: US153N64 | B4: Patton Alfred | C4: =COUNTIF('02_CLEAN_DATA'!$G$2:$G$570,A4) -> 15 | D4: =COUNTIFS('02_CLEAN_DATA'!$G$2:$G$570,A4,'02_CLEAN_DATA'!$R$2:$R$570,1) -> 8 | E4: =COUNTIFS('02_CLEAN_DATA'!$G$2:$G$570,A4,'02_CLEAN_DATA'!$W$2:$W$570,"Met") -> 6 | F4: =COUNTIFS('02_CLEAN_DATA'!$G$2:$G$570,A4,'02_CLEAN_DATA'!$W$2:$W$570,"Missed") -> 2 | G4: =IF(D4=0,"",E4/D4) -> 0.75 | H4: =COUNTIFS('02_CLEAN_DATA'!$G$2:$G$570,A4,'02_CLEAN_DATA'!$S$2:$S$570,"Customer Contracted Reasons") -> 9 | I4: =IFERROR(AVERAGEIF('02_CLEAN_DATA'!$G$2:$G$570,A4,'02_CLEAN_DATA'!$O$2:$O$570),"") -> 17.403333 | J4: {=IFERROR(MEDIAN(IF('02_CLEAN_DATA'!$G$2:$G$570=A4,'02_CLEAN_DATA'!$O$2:$O$570)),"")} -> 7.8 | K4: =IF(C4>=5,"Yes","No") -> Yes | L4: =IF(C4>=5,I4+ROW()/10000000,"") -> 17.403334 | M4: =F4+ROW()/10000000 -> 2.0000004
A5: US133E77 | B5: Ehret Alexander | C5: =COUNTIF('02_CLEAN_DATA'!$G$2:$G$570,A5) -> 14 | D5: =COUNTIFS('02_CLEAN_DATA'!$G$2:$G$570,A5,'02_CLEAN_DATA'!$R$2:$R$570,1) -> 3 | E5: =COUNTIFS('02_CLEAN_DATA'!$G$2:$G$570,A5,'02_CLEAN_DATA'!$W$2:$W$570,"Met") -> 2 | F5: =COUNTIFS('02_CLEAN_DATA'!$G$2:$G$570,A5,'02_CLEAN_DATA'!$W$2:$W$570,"Missed") -> 1 | G5: =IF(D5=0,"",E5/D5) -> 0.66666667 | H5: =COUNTIFS('02_CLEAN_DATA'!$G$2:$G$570,A5,'02_CLEAN_DATA'!$S$2:$S$570,"Customer Contracted Reasons") -> 8 | I5: =IFERROR(AVERAGEIF('02_CLEAN_DATA'!$G$2:$G$570,A5,'02_CLEAN_DATA'!$O$2:$O$570),"") -> 34.195714 | J5: {=IFERROR(MEDIAN(IF('02_CLEAN_DATA'!$G$2:$G$570=A5,'02_CLEAN_DATA'!$O$2:$O$570)),"")} -> 9.35 | K5: =IF(C5>=5,"Yes","No") -> Yes | L5: =IF(C5>=5,I5+ROW()/10000000,"") -> 34.195715 | M5: =F5+ROW()/10000000 -> 1.0000005
A6: US153N63 | B6: Vaughn Travis | C6: =COUNTIF('02_CLEAN_DATA'!$G$2:$G$570,A6) -> 14 | D6: =COUNTIFS('02_CLEAN_DATA'!$G$2:$G$570,A6,'02_CLEAN_DATA'!$R$2:$R$570,1) -> 8 | E6: =COUNTIFS('02_CLEAN_DATA'!$G$2:$G$570,A6,'02_CLEAN_DATA'!$W$2:$W$570,"Met") -> 7 | F6: =COUNTIFS('02_CLEAN_DATA'!$G$2:$G$570,A6,'02_CLEAN_DATA'!$W$2:$W$570,"Missed") -> 1 | G6: =IF(D6=0,"",E6/D6) -> 0.875 | H6: =COUNTIFS('02_CLEAN_DATA'!$G$2:$G$570,A6,'02_CLEAN_DATA'!$S$2:$S$570,"Customer Contracted Reasons") -> 8 | I6: =IFERROR(AVERAGEIF('02_CLEAN_DATA'!$G$2:$G$570,A6,'02_CLEAN_DATA'!$O$2:$O$570),"") -> 21.886429 | J6: {=IFERROR(MEDIAN(IF('02_CLEAN_DATA'!$G$2:$G$570=A6,'02_CLEAN_DATA'!$O$2:$O$570)),"")} -> 8.29 | K6: =IF(C6>=5,"Yes","No") -> Yes | L6: =IF(C6>=5,I6+ROW()/10000000,"") -> 21.886429 | M6: =F6+ROW()/10000000 -> 1.0000006
A7: US133E79 | B7: Qi Chuan | C7: =COUNTIF('02_CLEAN_DATA'!$G$2:$G$570,A7) -> 12 | D7: =COUNTIFS('02_CLEAN_DATA'!$G$2:$G$570,A7,'02_CLEAN_DATA'!$R$2:$R$570,1) -> 11 | E7: =COUNTIFS('02_CLEAN_DATA'!$G$2:$G$570,A7,'02_CLEAN_DATA'!$W$2:$W$570,"Met") -> 8 | F7: =COUNTIFS('02_CLEAN_DATA'!$G$2:$G$570,A7,'02_CLEAN_DATA'!$W$2:$W$570,"Missed") -> 3 | G7: =IF(D7=0,"",E7/D7) -> 0.72727273 | H7: =COUNTIFS('02_CLEAN_DATA'!$G$2:$G$570,A7,'02_CLEAN_DATA'!$S$2:$S$570,"Customer Contracted Reasons") -> 9 | I7: =IFERROR(AVERAGEIF('02_CLEAN_DATA'!$G$2:$G$570,A7,'02_CLEAN_DATA'!$O$2:$O$570),"") -> 44.696667 | J7: {=IFERROR(MEDIAN(IF('02_CLEAN_DATA'!$G$2:$G$570=A7,'02_CLEAN_DATA'!$O$2:$O$570)),"")} -> 25.915 | K7: =IF(C7>=5,"Yes","No") -> Yes | L7: =IF(C7>=5,I7+ROW()/10000000,"") -> 44.696667 | M7: =F7+ROW()/10000000 -> 3.0000007
A8: US133C72 | B8: McDonald Noah | C8: =COUNTIF('02_CLEAN_DATA'!$G$2:$G$570,A8) -> 11 | D8: =COUNTIFS('02_CLEAN_DATA'!$G$2:$G$570,A8,'02_CLEAN_DATA'!$R$2:$R$570,1) -> 11 | E8: =COUNTIFS('02_CLEAN_DATA'!$G$2:$G$570,A8,'02_CLEAN_DATA'!$W$2:$W$570,"Met") -> 10 | F8: =COUNTIFS('02_CLEAN_DATA'!$G$2:$G$570,A8,'02_CLEAN_DATA'!$W$2:$W$570,"Missed") -> 1 | G8: =IF(D8=0,"",E8/D8) -> 0.90909091 | H8: =COUNTIFS('02_CLEAN_DATA'!$G$2:$G$570,A8,'02_CLEAN_DATA'!$S$2:$S$570,"Customer Contracted Reasons") -> 11 | I8: =IFERROR(AVERAGEIF('02_CLEAN_DATA'!$G$2:$G$570,A8,'02_CLEAN_DATA'!$O$2:$O$570),"") -> 8.1190909 | J8: {=IFERROR(MEDIAN(IF('02_CLEAN_DATA'!$G$2:$G$570=A8,'02_CLEAN_DATA'!$O$2:$O$570)),"")} -> 3.37 | K8: =IF(C8>=5,"Yes","No") -> Yes | L8: =IF(C8>=5,I8+ROW()/10000000,"") -> 8.1190917 | M8: =F8+ROW()/10000000 -> 1.0000008
A9: US133U12 | B9: Rassam Zaid | C9: =COUNTIF('02_CLEAN_DATA'!$G$2:$G$570,A9) -> 11 | D9: =COUNTIFS('02_CLEAN_DATA'!$G$2:$G$570,A9,'02_CLEAN_DATA'!$R$2:$R$570,1) -> 11 | E9: =COUNTIFS('02_CLEAN_DATA'!$G$2:$G$570,A9,'02_CLEAN_DATA'!$W$2:$W$570,"Met") -> 11 | F9: =COUNTIFS('02_CLEAN_DATA'!$G$2:$G$570,A9,'02_CLEAN_DATA'!$W$2:$W$570,"Missed") -> 0 | G9: =IF(D9=0,"",E9/D9) -> 1 | H9: =COUNTIFS('02_CLEAN_DATA'!$G$2:$G$570,A9,'02_CLEAN_DATA'!$S$2:$S$570,"Customer Contracted Reasons") -> 9 | I9: =IFERROR(AVERAGEIF('02_CLEAN_DATA'!$G$2:$G$570,A9,'02_CLEAN_DATA'!$O$2:$O$570),"") -> 14.247273 | J9: {=IFERROR(MEDIAN(IF('02_CLEAN_DATA'!$G$2:$G$570=A9,'02_CLEAN_DATA'!$O$2:$O$570)),"")} -> 14.55 | K9: =IF(C9>=5,"Yes","No") -> Yes | L9: =IF(C9>=5,I9+ROW()/10000000,"") -> 14.247274 | M9: =F9+ROW()/10000000 -> 9e-07
A10: US133A17 | B10: Blain Simon | C10: =COUNTIF('02_CLEAN_DATA'!$G$2:$G$570,A10) -> 10 | D10: =COUNTIFS('02_CLEAN_DATA'!$G$2:$G$570,A10,'02_CLEAN_DATA'!$R$2:$R$570,1) -> 8 | E10: =COUNTIFS('02_CLEAN_DATA'!$G$2:$G$570,A10,'02_CLEAN_DATA'!$W$2:$W$570,"Met") -> 7 | F10: =COUNTIFS('02_CLEAN_DATA'!$G$2:$G$570,A10,'02_CLEAN_DATA'!$W$2:$W$570,"Missed") -> 1 | G10: =IF(D10=0,"",E10/D10) -> 0.875 | H10: =COUNTIFS('02_CLEAN_DATA'!$G$2:$G$570,A10,'02_CLEAN_DATA'!$S$2:$S$570,"Customer Contracted Reasons") -> 9 | I10: =IFERROR(AVERAGEIF('02_CLEAN_DATA'!$G$2:$G$570,A10,'02_CLEAN_DATA'!$O$2:$O$570),"") -> 25.446 | J10: {=IFERROR(MEDIAN(IF('02_CLEAN_DATA'!$G$2:$G$570=A10,'02_CLEAN_DATA'!$O$2:$O$570)),"")} -> 25.075 | K10: =IF(C10>=5,"Yes","No") -> Yes | L10: =IF(C10>=5,I10+ROW()/10000000,"") -> 25.446001 | M10: =F10+ROW()/10000000 -> 1.000001
A11: US153C10 | B11: Droste Michael | C11: =COUNTIF('02_CLEAN_DATA'!$G$2:$G$570,A11) -> 10 | D11: =COUNTIFS('02_CLEAN_DATA'!$G$2:$G$570,A11,'02_CLEAN_DATA'!$R$2:$R$570,1) -> 10 | E11: =COUNTIFS('02_CLEAN_DATA'!$G$2:$G$570,A11,'02_CLEAN_DATA'!$W$2:$W$570,"Met") -> 4 | F11: =COUNTIFS('02_CLEAN_DATA'!$G$2:$G$570,A11,'02_CLEAN_DATA'!$W$2:$W$570,"Missed") -> 6 | G11: =IF(D11=0,"",E11/D11) -> 0.4 | H11: =COUNTIFS('02_CLEAN_DATA'!$G$2:$G$570,A11,'02_CLEAN_DATA'!$S$2:$S$570,"Customer Contracted Reasons") -> 7 | I11: =IFERROR(AVERAGEIF('02_CLEAN_DATA'!$G$2:$G$570,A11,'02_CLEAN_DATA'!$O$2:$O$570),"") -> 44.176 | J11: {=IFERROR(MEDIAN(IF('02_CLEAN_DATA'!$G$2:$G$570=A11,'02_CLEAN_DATA'!$O$2:$O$570)),"")} -> 54.71 | K11: =IF(C11>=5,"Yes","No") -> Yes | L11: =IF(C11>=5,I11+ROW()/10000000,"") -> 44.176001 | M11: =F11+ROW()/10000000 -> 6.0000011
A12: US153N60 | B12: Welton Kira | C12: =COUNTIF('02_CLEAN_DATA'!$G$2:$G$570,A12) -> 10 | D12: =COUNTIFS('02_CLEAN_DATA'!$G$2:$G$570,A12,'02_CLEAN_DATA'!$R$2:$R$570,1) -> 5 | E12: =COUNTIFS('02_CLEAN_DATA'!$G$2:$G$570,A12,'02_CLEAN_DATA'!$W$2:$W$570,"Met") -> 5 | F12: =COUNTIFS('02_CLEAN_DATA'!$G$2:$G$570,A12,'02_CLEAN_DATA'!$W$2:$W$570,"Missed") -> 0 | G12: =IF(D12=0,"",E12/D12) -> 1 | H12: =COUNTIFS('02_CLEAN_DATA'!$G$2:$G$570,A12,'02_CLEAN_DATA'!$S$2:$S$570,"Customer Contracted Reasons") -> 5 | I12: =IFERROR(AVERAGEIF('02_CLEAN_DATA'!$G$2:$G$570,A12,'02_CLEAN_DATA'!$O$2:$O$570),"") -> 14.192 | J12: {=IFERROR(MEDIAN(IF('02_CLEAN_DATA'!$G$2:$G$570=A12,'02_CLEAN_DATA'!$O$2:$O$570)),"")} -> 8.885 | K12: =IF(C12>=5,"Yes","No") -> Yes | L12: =IF(C12>=5,I12+ROW()/10000000,"") -> 14.192001 | M12: =F12+ROW()/10000000 -> 1.2e-06
A13: US133C52 | B13: Bullock Todd | C13: =COUNTIF('02_CLEAN_DATA'!$G$2:$G$570,A13) -> 9 | D13: =COUNTIFS('02_CLEAN_DATA'!$G$2:$G$570,A13,'02_CLEAN_DATA'!$R$2:$R$570,1) -> 7 | E13: =COUNTIFS('02_CLEAN_DATA'!$G$2:$G$570,A13,'02_CLEAN_DATA'!$W$2:$W$570,"Met") -> 7 | F13: =COUNTIFS('02_CLEAN_DATA'!$G$2:$G$570,A13,'02_CLEAN_DATA'!$W$2:$W$570,"Missed") -> 0 | G13: =IF(D13=0,"",E13/D13) -> 1 | H13: =COUNTIFS('02_CLEAN_DATA'!$G$2:$G$570,A13,'02_CLEAN_DATA'!$S$2:$S$570,"Customer Contracted Reasons") -> 3 | I13: =IFERROR(AVERAGEIF('02_CLEAN_DATA'!$G$2:$G$570,A13,'02_CLEAN_DATA'!$O$2:$O$570),"") -> 5.3944444 | J13: {=IFERROR(MEDIAN(IF('02_CLEAN_DATA'!$G$2:$G$570=A13,'02_CLEAN_DATA'!$O$2:$O$570)),"")} -> 3.35 | K13: =IF(C13>=5,"Yes","No") -> Yes | L13: =IF(C13>=5,I13+ROW()/10000000,"") -> 5.3944457 | M13: =F13+ROW()/10000000 -> 1.3e-06
... A152: US153R84 | B152: Ford Ethan | C152: =COUNTIF('02_CLEAN_DATA'!$G$2:$G$570,A152) -> 1 | D152: =COUNTIFS('02_CLEAN_DATA'!$G$2:$G$570,A152,'02_CLEAN_DATA'!$R$2:$R$570,1) -> 1 | E152: =COUNTIFS('02_CLEAN_DATA'!$G$2:$G$570,A152,'02_CLEAN_DATA'!$W$2:$W$570,"Met") -> 1 | F152: =COUNTIFS('02_CLEAN_DATA'!$G$2:$G$570,A152,'02_CLEAN_DATA'!$W$2:$W$570,"Missed") -> 0 | G152: =IF(D152=0,"",E152/D152) -> 1 | H152: =COUNTIFS('02_CLEAN_DATA'!$G$2:$G$570,A152,'02_CLEAN_DATA'!$S$2:$S$570,"Customer Contracted Reasons") -> 1 | I152: =IFERROR(AVERAGEIF('02_CLEAN_DATA'!$G$2:$G$570,A152,'02_CLEAN_DATA'!$O$2:$O$570),"") -> 17.73 | J152: {=IFERROR(MEDIAN(IF('02_CLEAN_DATA'!$G$2:$G$570=A152,'02_CLEAN_DATA'!$O$2:$O$570)),"")} -> 17.73 | K152: =IF(C152>=5,"Yes","No") -> No | L152: =IF(C152>=5,I152+ROW()/10000000,"") | M152: =F152+ROW()/10000000 -> 1.52e-05
A155: Note: Minimum-ticket threshold of 5 SLA-relevant tickets is used to identify technicians with statistically meaningful performance differences (Column K). Technicians below threshold are listed for completeness but excluded from ranked comparisons in the PowerPoint and Advanced Insights tab.

Sheet 08_RESOLUTION_ANALYSIS
A1: Resolution Time Analysis
A3: Overall (All Closed Tickets)
A4: Average Resolution Time (Hrs) | B4: =AVERAGE('02_CLEAN_DATA'!$O$2:$O$570) -> 30.227606
A5: Median Resolution Time (Hrs) | B5: {=MEDIAN('02_CLEAN_DATA'!$O$2:$O$570)} -> 14.04
A6: Minimum (Hrs) | B6: =MIN('02_CLEAN_DATA'!$O$2:$O$570) -> 0.13
A7: 90th Percentile (Hrs) | B7: =PERCENTILE('02_CLEAN_DATA'!$O$2:$O$570,0.9) -> 73.947
A8: Maximum (Hrs) | B8: =MAX('02_CLEAN_DATA'!$O$2:$O$570) -> 672.22
A10: By Severity
A11: Severity | B11: Tickets | C11: SLA Eligible | D11: SLA Met | E11: SLA % | F11: Avg Resolution (Hrs) | G11: Median Resolution (Hrs)
A12: Severity 1 | B12: =COUNTIF('02_CLEAN_DATA'!$H$2:$H$570,1) -> 103 | C12: =COUNTIFS('02_CLEAN_DATA'!$H$2:$H$570,1,'02_CLEAN_DATA'!$R$2:$R$570,1) -> 81 | D12: =COUNTIFS('02_CLEAN_DATA'!$H$2:$H$570,1,'02_CLEAN_DATA'!$W$2:$W$570,"Met") -> 63 | E12: =IF(C12=0,"",D12/C12) -> 0.77777778 | F12: =IFERROR(AVERAGEIF('02_CLEAN_DATA'!$H$2:$H$570,1,'02_CLEAN_DATA'!$O$2:$O$570),"") -> 20.231359 | G12: {=IFERROR(MEDIAN(IF('02_CLEAN_DATA'!$H$2:$H$570=1,'02_CLEAN_DATA'!$O$2:$O$570)),"")} -> 6.58
A13: Severity 2 | B13: =COUNTIF('02_CLEAN_DATA'!$H$2:$H$570,2) -> 466 | C13: =COUNTIFS('02_CLEAN_DATA'!$H$2:$H$570,2,'02_CLEAN_DATA'!$R$2:$R$570,1) -> 354 | D13: =COUNTIFS('02_CLEAN_DATA'!$H$2:$H$570,2,'02_CLEAN_DATA'!$W$2:$W$570,"Met") -> 274 | E13: =IF(C13=0,"",D13/C13) -> 0.7740113 | F13: =IFERROR(AVERAGEIF('02_CLEAN_DATA'!$H$2:$H$570,2,'02_CLEAN_DATA'!$O$2:$O$570),"") -> 32.441828 | G13: {=IFERROR(MEDIAN(IF('02_CLEAN_DATA'!$H$2:$H$570=2,'02_CLEAN_DATA'!$O$2:$O$570)),"")} -> 14.915
A16: By Month
A17: Month | B17: Avg Resolution (Hrs) | C17: Median Resolution (Hrs)
A18: 2025-08 | B18: =IFERROR(AVERAGEIF('02_CLEAN_DATA'!$L$2:$L$570,A18,'02_CLEAN_DATA'!$O$2:$O$570),"") -> 32.271282 | C18: {=IFERROR(MEDIAN(IF('02_CLEAN_DATA'!$L$2:$L$570=A18,'02_CLEAN_DATA'!$O$2:$O$570)),"")} -> 21.25
A19: 2025-09 | B19: =IFERROR(AVERAGEIF('02_CLEAN_DATA'!$L$2:$L$570,A19,'02_CLEAN_DATA'!$O$2:$O$570),"") -> 42.746316 | C19: {=IFERROR(MEDIAN(IF('02_CLEAN_DATA'!$L$2:$L$570=A19,'02_CLEAN_DATA'!$O$2:$O$570)),"")} -> 14.85
A20: 2025-10 | B20: =IFERROR(AVERAGEIF('02_CLEAN_DATA'!$L$2:$L$570,A20,'02_CLEAN_DATA'!$O$2:$O$570),"") -> 41.202321 | C20: {=IFERROR(MEDIAN(IF('02_CLEAN_DATA'!$L$2:$L$570=A20,'02_CLEAN_DATA'!$O$2:$O$570)),"")} -> 20.875
A21: 2025-11 | B21: =IFERROR(AVERAGEIF('02_CLEAN_DATA'!$L$2:$L$570,A21,'02_CLEAN_DATA'!$O$2:$O$570),"") -> 59.275227 | C21: {=IFERROR(MEDIAN(IF('02_CLEAN_DATA'!$L$2:$L$570=A21,'02_CLEAN_DATA'!$O$2:$O$570)),"")} -> 15.5
A22: 2025-12 | B22: =IFERROR(AVERAGEIF('02_CLEAN_DATA'!$L$2:$L$570,A22,'02_CLEAN_DATA'!$O$2:$O$570),"") -> 23.1098 | C22: {=IFERROR(MEDIAN(IF('02_CLEAN_DATA'!$L$2:$L$570=A22,'02_CLEAN_DATA'!$O$2:$O$570)),"")} -> 12.67
A23: 2026-01 | B23: =IFERROR(AVERAGEIF('02_CLEAN_DATA'!$L$2:$L$570,A23,'02_CLEAN_DATA'!$O$2:$O$570),"") -> 22.958246 | C23: {=IFERROR(MEDIAN(IF('02_CLEAN_DATA'!$L$2:$L$570=A23,'02_CLEAN_DATA'!$O$2:$O$570)),"")} -> 4.13
A24: 2026-02 | B24: =IFERROR(AVERAGEIF('02_CLEAN_DATA'!$L$2:$L$570,A24,'02_CLEAN_DATA'!$O$2:$O$570),"") -> 11.812439 | C24: {=IFERROR(MEDIAN(IF('02_CLEAN_DATA'!$L$2:$L$570=A24,'02_CLEAN_DATA'!$O$2:$O$570)),"")} -> 3.48
A25: 2026-03 | B25: =IFERROR(AVERAGEIF('02_CLEAN_DATA'!$L$2:$L$570,A25,'02_CLEAN_DATA'!$O$2:$O$570),"") -> 31.538889 | C25: {=IFERROR(MEDIAN(IF('02_CLEAN_DATA'!$L$2:$L$570=A25,'02_CLEAN_DATA'!$O$2:$O$570)),"")} -> 17.63
A26: 2026-04 | B26: =IFERROR(AVERAGEIF('02_CLEAN_DATA'!$L$2:$L$570,A26,'02_CLEAN_DATA'!$O$2:$O$570),"") -> 15.99125 | C26: {=IFERROR(MEDIAN(IF('02_CLEAN_DATA'!$L$2:$L$570=A26,'02_CLEAN_DATA'!$O$2:$O$570)),"")} -> 6.84
A27: 2026-05 | B27: =IFERROR(AVERAGEIF('02_CLEAN_DATA'!$L$2:$L$570,A27,'02_CLEAN_DATA'!$O$2:$O$570),"") -> 20.961053 | C27: {=IFERROR(MEDIAN(IF('02_CLEAN_DATA'!$L$2:$L$570=A27,'02_CLEAN_DATA'!$O$2:$O$570)),"")} -> 14.525
A28: 2026-06 | B28: =IFERROR(AVERAGEIF('02_CLEAN_DATA'!$L$2:$L$570,A28,'02_CLEAN_DATA'!$O$2:$O$570),"") -> 30.885952 | C28: {=IFERROR(MEDIAN(IF('02_CLEAN_DATA'!$L$2:$L$570=A28,'02_CLEAN_DATA'!$O$2:$O$570)),"")} -> 20.125
A29: 2026-07 | B29: =IFERROR(AVERAGEIF('02_CLEAN_DATA'!$L$2:$L$570,A29,'02_CLEAN_DATA'!$O$2:$O$570),"") -> 30.18186 | C29: {=IFERROR(MEDIAN(IF('02_CLEAN_DATA'!$L$2:$L$570=A29,'02_CLEAN_DATA'!$O$2:$O$570)),"")} -> 16.55
A30: 2026-08 | B30: =IFERROR(AVERAGEIF('02_CLEAN_DATA'!$L$2:$L$570,A30,'02_CLEAN_DATA'!$O$2:$O$570),"") -> 9.990625 | C30: {=IFERROR(MEDIAN(IF('02_CLEAN_DATA'!$L$2:$L$570=A30,'02_CLEAN_DATA'!$O$2:$O$570)),"")} -> 5.61
A34: Slowest Stores (Avg Resolution, min. 5 tickets) | F34: Fastest Stores (Avg Resolution, min. 5 tickets)
A35: Rank | B35: Store | C35: Avg Resolution (Hrs) | D35: SLA % | F35: Rank | G35: Store | H35: Avg Resolution (Hrs) | I35: SLA %
A36: 1 | B36: {=IFERROR(INDEX('06_STORE_ANALYSIS'!$B$2:$B$70,MATCH(LARGE('06_STORE_ANALYSIS'!$N$2:$N$70,1),'06_STORE_ANALYSIS'!$N$2:$N$70,0)),"")} -> Fresh Thyme #545 | C36: {=IFERROR(INDEX('06_STORE_ANALYSIS'!$L$2:$L$70,MATCH(LARGE('06_STORE_ANALYSIS'!$N$2:$N$70,1),'06_STORE_ANALYSIS'!$N$2:$N$70,0)),"")} -> 104.00714 | D36: {=IFERROR(INDEX('06_STORE_ANALYSIS'!$I$2:$I$70,MATCH(LARGE('06_STORE_ANALYSIS'!$N$2:$N$70,1),'06_STORE_ANALYSIS'!$N$2:$N$70,0)),"")} -> 0.8 | F36: 1 | G36: {=IFERROR(INDEX('06_STORE_ANALYSIS'!$B$2:$B$70,MATCH(SMALL('06_STORE_ANALYSIS'!$N$2:$N$70,1),'06_STORE_ANALYSIS'!$N$2:$N$70,0)),"")} -> Fresh Thyme #639 | H36: {=IFERROR(INDEX('06_STORE_ANALYSIS'!$L$2:$L$70,MATCH(SMALL('06_STORE_ANALYSIS'!$N$2:$N$70,1),'06_STORE_ANALYSIS'!$N$2:$N$70,0)),"")} -> 4.5523077 | I36: {=IFERROR(INDEX('06_STORE_ANALYSIS'!$I$2:$I$70,MATCH(SMALL('06_STORE_ANALYSIS'!$N$2:$N$70,1),'06_STORE_ANALYSIS'!$N$2:$N$70,0)),"")} -> 1
A37: 2 | B37: {=IFERROR(INDEX('06_STORE_ANALYSIS'!$B$2:$B$70,MATCH(LARGE('06_STORE_ANALYSIS'!$N$2:$N$70,2),'06_STORE_ANALYSIS'!$N$2:$N$70,0)),"")} -> Fresh Thyme #647 | C37: {=IFERROR(INDEX('06_STORE_ANALYSIS'!$L$2:$L$70,MATCH(LARGE('06_STORE_ANALYSIS'!$N$2:$N$70,2),'06_STORE_ANALYSIS'!$N$2:$N$70,0)),"")} -> 85.784375 | D37: {=IFERROR(INDEX('06_STORE_ANALYSIS'!$I$2:$I$70,MATCH(LARGE('06_STORE_ANALYSIS'!$N$2:$N$70,2),'06_STORE_ANALYSIS'!$N$2:$N$70,0)),"")} -> 0.28571429 | F37: 2 | G37: {=IFERROR(INDEX('06_STORE_ANALYSIS'!$B$2:$B$70,MATCH(SMALL('06_STORE_ANALYSIS'!$N$2:$N$70,2),'06_STORE_ANALYSIS'!$N$2:$N$70,0)),"")} -> Fresh Thyme #921 | H37: {=IFERROR(INDEX('06_STORE_ANALYSIS'!$L$2:$L$70,MATCH(SMALL('06_STORE_ANALYSIS'!$N$2:$N$70,2),'06_STORE_ANALYSIS'!$N$2:$N$70,0)),"")} -> 6.8442857 | I37: {=IFERROR(INDEX('06_STORE_ANALYSIS'!$I$2:$I$70,MATCH(SMALL('06_STORE_ANALYSIS'!$N$2:$N$70,2),'06_STORE_ANALYSIS'!$N$2:$N$70,0)),"")} -> 1
A38: 3 | B38: {=IFERROR(INDEX('06_STORE_ANALYSIS'!$B$2:$B$70,MATCH(LARGE('06_STORE_ANALYSIS'!$N$2:$N$70,3),'06_STORE_ANALYSIS'!$N$2:$N$70,0)),"")} -> Fresh Thyme #522 | C38: {=IFERROR(INDEX('06_STORE_ANALYSIS'!$L$2:$L$70,MATCH(LARGE('06_STORE_ANALYSIS'!$N$2:$N$70,3),'06_STORE_ANALYSIS'!$N$2:$N$70,0)),"")} -> 72.347692 | D38: {=IFERROR(INDEX('06_STORE_ANALYSIS'!$I$2:$I$70,MATCH(LARGE('06_STORE_ANALYSIS'!$N$2:$N$70,3),'06_STORE_ANALYSIS'!$N$2:$N$70,0)),"")} -> 0.58333333 | F38: 3 | G38: {=IFERROR(INDEX('06_STORE_ANALYSIS'!$B$2:$B$70,MATCH(SMALL('06_STORE_ANALYSIS'!$N$2:$N$70,3),'06_STORE_ANALYSIS'!$N$2:$N$70,0)),"")} -> Fresh Thyme #524 | H38: {=IFERROR(INDEX('06_STORE_ANALYSIS'!$L$2:$L$70,MATCH(SMALL('06_STORE_ANALYSIS'!$N$2:$N$70,3),'06_STORE_ANALYSIS'!$N$2:$N$70,0)),"")} -> 8.0388889 | I38: {=IFERROR(INDEX('06_STORE_ANALYSIS'!$I$2:$I$70,MATCH(SMALL('06_STORE_ANALYSIS'!$N$2:$N$70,3),'06_STORE_ANALYSIS'!$N$2:$N$70,0)),"")} -> 0.875
A39: 4 | B39: {=IFERROR(INDEX('06_STORE_ANALYSIS'!$B$2:$B$70,MATCH(LARGE('06_STORE_ANALYSIS'!$N$2:$N$70,4),'06_STORE_ANALYSIS'!$N$2:$N$70,0)),"")} -> Fresh Thyme #542 | C39: {=IFERROR(INDEX('06_STORE_ANALYSIS'!$L$2:$L$70,MATCH(LARGE('06_STORE_ANALYSIS'!$N$2:$N$70,4),'06_STORE_ANALYSIS'!$N$2:$N$70,0)),"")} -> 70.924 | D39: {=IFERROR(INDEX('06_STORE_ANALYSIS'!$I$2:$I$70,MATCH(LARGE('06_STORE_ANALYSIS'!$N$2:$N$70,4),'06_STORE_ANALYSIS'!$N$2:$N$70,0)),"")} -> 0.8 | F39: 4 | G39: {=IFERROR(INDEX('06_STORE_ANALYSIS'!$B$2:$B$70,MATCH(SMALL('06_STORE_ANALYSIS'!$N$2:$N$70,4),'06_STORE_ANALYSIS'!$N$2:$N$70,0)),"")} -> Fresh Thyme #645 | H39: {=IFERROR(INDEX('06_STORE_ANALYSIS'!$L$2:$L$70,MATCH(SMALL('06_STORE_ANALYSIS'!$N$2:$N$70,4),'06_STORE_ANALYSIS'!$N$2:$N$70,0)),"")} -> 8.4428571 | I39: {=IFERROR(INDEX('06_STORE_ANALYSIS'!$I$2:$I$70,MATCH(SMALL('06_STORE_ANALYSIS'!$N$2:$N$70,4),'06_STORE_ANALYSIS'!$N$2:$N$70,0)),"")} -> 1
A40: 5 | B40: {=IFERROR(INDEX('06_STORE_ANALYSIS'!$B$2:$B$70,MATCH(LARGE('06_STORE_ANALYSIS'!$N$2:$N$70,5),'06_STORE_ANALYSIS'!$N$2:$N$70,0)),"")} -> Fresh Thyme #546 | C40: {=IFERROR(INDEX('06_STORE_ANALYSIS'!$L$2:$L$70,MATCH(LARGE('06_STORE_ANALYSIS'!$N$2:$N$70,5),'06_STORE_ANALYSIS'!$N$2:$N$70,0)),"")} -> 65.364 | D40: {=IFERROR(INDEX('06_STORE_ANALYSIS'!$I$2:$I$70,MATCH(LARGE('06_STORE_ANALYSIS'!$N$2:$N$70,5),'06_STORE_ANALYSIS'!$N$2:$N$70,0)),"")} -> 0.72727273 | F40: 5 | G40: {=IFERROR(INDEX('06_STORE_ANALYSIS'!$B$2:$B$70,MATCH(SMALL('06_STORE_ANALYSIS'!$N$2:$N$70,5),'06_STORE_ANALYSIS'!$N$2:$N$70,0)),"")} -> Fresh Thyme #649 | H40: {=IFERROR(INDEX('06_STORE_ANALYSIS'!$L$2:$L$70,MATCH(SMALL('06_STORE_ANALYSIS'!$N$2:$N$70,5),'06_STORE_ANALYSIS'!$N$2:$N$70,0)),"")} -> 8.7842857 | I40: {=IFERROR(INDEX('06_STORE_ANALYSIS'!$I$2:$I$70,MATCH(SMALL('06_STORE_ANALYSIS'!$N$2:$N$70,5),'06_STORE_ANALYSIS'!$N$2:$N$70,0)),"")} -> 1
A41: 6 | B41: {=IFERROR(INDEX('06_STORE_ANALYSIS'!$B$2:$B$70,MATCH(LARGE('06_STORE_ANALYSIS'!$N$2:$N$70,6),'06_STORE_ANALYSIS'!$N$2:$N$70,0)),"")} -> Fresh Thyme #562 | C41: {=IFERROR(INDEX('06_STORE_ANALYSIS'!$L$2:$L$70,MATCH(LARGE('06_STORE_ANALYSIS'!$N$2:$N$70,6),'06_STORE_ANALYSIS'!$N$2:$N$70,0)),"")} -> 63.572 | D41: {=IFERROR(INDEX('06_STORE_ANALYSIS'!$I$2:$I$70,MATCH(LARGE('06_STORE_ANALYSIS'!$N$2:$N$70,6),'06_STORE_ANALYSIS'!$N$2:$N$70,0)),"")} -> 0.72727273 | F41: 6 | G41: {=IFERROR(INDEX('06_STORE_ANALYSIS'!$B$2:$B$70,MATCH(SMALL('06_STORE_ANALYSIS'!$N$2:$N$70,6),'06_STORE_ANALYSIS'!$N$2:$N$70,0)),"")} -> Fresh Thyme #537 | H41: {=IFERROR(INDEX('06_STORE_ANALYSIS'!$L$2:$L$70,MATCH(SMALL('06_STORE_ANALYSIS'!$N$2:$N$70,6),'06_STORE_ANALYSIS'!$N$2:$N$70,0)),"")} -> 9.3744444 | I41: {=IFERROR(INDEX('06_STORE_ANALYSIS'!$I$2:$I$70,MATCH(SMALL('06_STORE_ANALYSIS'!$N$2:$N$70,6),'06_STORE_ANALYSIS'!$N$2:$N$70,0)),"")} -> 1
A42: 7 | B42: {=IFERROR(INDEX('06_STORE_ANALYSIS'!$B$2:$B$70,MATCH(LARGE('06_STORE_ANALYSIS'!$N$2:$N$70,7),'06_STORE_ANALYSIS'!$N$2:$N$70,0)),"")} -> Fresh Thyme #931 | C42: {=IFERROR(INDEX('06_STORE_ANALYSIS'!$L$2:$L$70,MATCH(LARGE('06_STORE_ANALYSIS'!$N$2:$N$70,7),'06_STORE_ANALYSIS'!$N$2:$N$70,0)),"")} -> 63.534118 | D42: {=IFERROR(INDEX('06_STORE_ANALYSIS'!$I$2:$I$70,MATCH(LARGE('06_STORE_ANALYSIS'!$N$2:$N$70,7),'06_STORE_ANALYSIS'!$N$2:$N$70,0)),"")} -> 0.41666667 | F42: 7 | G42: {=IFERROR(INDEX('06_STORE_ANALYSIS'!$B$2:$B$70,MATCH(SMALL('06_STORE_ANALYSIS'!$N$2:$N$70,7),'06_STORE_ANALYSIS'!$N$2:$N$70,0)),"")} -> Fresh Thyme #968 | H42: {=IFERROR(INDEX('06_STORE_ANALYSIS'!$L$2:$L$70,MATCH(SMALL('06_STORE_ANALYSIS'!$N$2:$N$70,7),'06_STORE_ANALYSIS'!$N$2:$N$70,0)),"")} -> 9.4383333 | I42: {=IFERROR(INDEX('06_STORE_ANALYSIS'!$I$2:$I$70,MATCH(SMALL('06_STORE_ANALYSIS'!$N$2:$N$70,7),'06_STORE_ANALYSIS'!$N$2:$N$70,0)),"")} -> 1
A43: 8 | B43: {=IFERROR(INDEX('06_STORE_ANALYSIS'!$B$2:$B$70,MATCH(LARGE('06_STORE_ANALYSIS'!$N$2:$N$70,8),'06_STORE_ANALYSIS'!$N$2:$N$70,0)),"")} -> Fresh Thyme #541 | C43: {=IFERROR(INDEX('06_STORE_ANALYSIS'!$L$2:$L$70,MATCH(LARGE('06_STORE_ANALYSIS'!$N$2:$N$70,8),'06_STORE_ANALYSIS'!$N$2:$N$70,0)),"")} -> 59.23125 | D43: {=IFERROR(INDEX('06_STORE_ANALYSIS'!$I$2:$I$70,MATCH(LARGE('06_STORE_ANALYSIS'!$N$2:$N$70,8),'06_STORE_ANALYSIS'!$N$2:$N$70,0)),"")} -> 0.5 | F43: 8 | G43: {=IFERROR(INDEX('06_STORE_ANALYSIS'!$B$2:$B$70,MATCH(SMALL('06_STORE_ANALYSIS'!$N$2:$N$70,8),'06_STORE_ANALYSIS'!$N$2:$N$70,0)),"")} -> Fresh Thyme #525 | H43: {=IFERROR(INDEX('06_STORE_ANALYSIS'!$L$2:$L$70,MATCH(SMALL('06_STORE_ANALYSIS'!$N$2:$N$70,8),'06_STORE_ANALYSIS'!$N$2:$N$70,0)),"")} -> 9.7522222 | I43: {=IFERROR(INDEX('06_STORE_ANALYSIS'!$I$2:$I$70,MATCH(SMALL('06_STORE_ANALYSIS'!$N$2:$N$70,8),'06_STORE_ANALYSIS'!$N$2:$N$70,0)),"")} -> 1
