Workbook

Sheet Dashboard
A1: MEIJER SLA PERFORMANCE DASHBOARD
A2: Reporting Period: February 2025 – June 2026
A4: AVERAGE SLA % | C4: TARGET SLA | E4: TOTAL TICKETS | G4: MONTHS ABOVE TARGET
A5: =Monthly_Summary!B24 -> 0.90882353 | C5: =Monthly_Summary!B4 -> 0.85 | E5: =Monthly_Summary!B26 -> 17999 | G5: =Monthly_Summary!B29&" of "&Monthly_Summary!B30 -> 17 of 17
A9: BEST MONTH | C9: BEST MONTH SLA | E9: LOWEST MONTH | G9: LOWEST MONTH SLA
A10: =Monthly_Summary!A32 -> Best Month (SLA) | C10: =Monthly_Summary!B33 -> 0.94 | E10: =Monthly_Summary!A34 -> Worst Month (SLA) | G10: =Monthly_Summary!B35 -> 0.85
A14: Filters: | B14: Month | C14: (All) | D14: Store | E14: (All)
A15: Note: dropdown filters shown above. Native Excel Slicers require converting Pivot_Tables data into real PivotTables via Insert > PivotTable, then Insert > Slicer.

Sheet Raw_Data
A1: Meijer SLA Program — Raw Data (Feb 2025–Jun 2026)
A2: Source: Meijer_Presentation_Prep.xlsx (client-provided); normalized and data-quality corrected — see notes
A4: Overall Monthly SLA Performance
A5: Month | B5: Target SLA | C5: Actual SLA % | D5: Tickets Created
A6: Feb-25 | B6: 0.85 | C6: 0.85 | D6: 1290
A7: Mar-25 | B7: 0.85 | C7: 0.86 | D7: 1416
A8: Apr-25 | B8: 0.85 | C8: 0.87 | D8: 1225
A9: May-25 | B9: 0.85 | C9: 0.93 | D9: 994
A10: Jun-25 | B10: 0.85 | C10: 0.91 | D10: 725
A11: Jul-25 | B11: 0.85 | C11: 0.93 | D11: 818
A12: Aug-25 | B12: 0.85 | C12: 0.92 | D12: 711
A13: Sep-25 | B13: 0.85 | C13: 0.9 | D13: 828
A14: Oct-25 | B14: 0.85 | C14: 0.92 | D14: 822
A15: Nov-25 | B15: 0.85 | C15: 0.9 | D15: 993
A16: Dec-25 | B16: 0.85 | C16: 0.89 | D16: 1006
A17: Jan-26 | B17: 0.85 | C17: 0.93 | D17: 1141
... A22: Jun-26 | B22: 0.85 | C22: 0.92 | D22: 1208
A25: VIP Store Master List
A26: Store Number | B26: City
A27: Meijer #033 | B27: Traverse City
A28: Meijer #047 | B28: Holland
A29: Meijer #050 | B29: Cascade
A30: Meijer #056 | B30: Jackson
A31: Meijer #108 | B31: Midland
A32: Meijer #119 | B32: Kalamazoo
A33: Meijer #158 | B33: Knapps Corner
A34: Meijer #199 | B34: Caledonia
A35: Meijer #216 | B35: Standale
A36: Meijer #226 | B36: Algoma
A39: VIP Store Monthly Detail (Ticket Count / SLA %)
A40: Store Number | B40: City | C40: Feb-25 Tickets | D40: Feb-25 SLA% | E40: Mar-25 Tickets | F40: Mar-25 SLA% | G40: Apr-25 Tickets | H40: Apr-25 SLA% | I40: May-25 Tickets | J40: May-25 SLA% | K40: Jun-25 Tickets | L40: Jun-25 SLA% | M40: Jul-25 Tickets | N40: Jul-25 SLA% | O40: Aug-25 Tickets | P40: Aug-25 SLA% | Q40: Sep-25 Tickets | R40: Sep-25 SLA% | S40: Oct-25 Tickets | T40: Oct-25 SLA% | U40: Nov-25 Tickets | V40: Nov-25 SLA% | W40: Dec-25 Tickets | X40: Dec-25 SLA% | Y40: Jan-26 Tickets | Z40: Jan-26 SLA% | AA40: Feb-26 Tickets | AB40: Feb-26 SLA% | AC40: Mar-26 Tickets | AD40: Mar-26 SLA% | AE40: Apr-26 Tickets | AF40: Apr-26 SLA% | AG40: May-26 Tickets | AH40: May-26 SLA% | AI40: Jun-26 Tickets | AJ40: Jun-26 SLA%
A41: Meijer #033 | B41: Traverse City | C41: 8 | D41: 0.25 | E41: 4 | F41: 1 | G41: 11 | H41: 0.73 | I41: 3 | J41: 1 | K41: 1 | L41: 1 | M41: N/A | N41: N/A | O41: N/A | P41: N/A | Q41: 2 | R41: 1 | S41: 2 | T41: 1 | U41: 2 | V41: 1 | W41: 2 | X41: 1 | Y41: 10 | Z41: 0.8 | AA41: 6 | AB41: 1 | AC41: 36 | AD41: 0.97 | AE41: 7 | AF41: 0.86 | AG41: 1 | AH41: 1 | AI41: 1 | AJ41: 1
A42: Meijer #047 | B42: Holland | C42: 2 | D42: 1 | E42: 9 | F42: 1 | G42: 2 | H42: 1 | I42: 5 | J42: 1 | K42: 6 | L42: 0.83 | M42: N/A | N42: N/A | O42: N/A | P42: N/A | Q42: N/A | R42: N/A | S42: 1 | T42: 1 | U42: N/A | V42: N/A | W42: 4 | X42: 1 | Y42: 5 | Z42: 1 | AA42: 10 | AB42: 1 | AC42: 6 | AD42: 1 | AE42: 3 | AF42: 1 | AG42: 8 | AH42: 1 | AI42: 2 | AJ42: 1
A43: Meijer #050 | B43: Cascade | C43: 22 | D43: 0.86 | E43: 12 | F43: 0.83 | G43: 5 | H43: 1 | I43: 9 | J43: 1 | K43: 4 | L43: 0.83 | M43: N/A | N43: N/A | O43: N/A | P43: N/A | Q43: N/A | R43: N/A | S43: N/A | T43: N/A | U43: N/A | V43: N/A | W43: 2 | X43: 1 | Y43: 5 | Z43: 1 | AA43: 2 | AB43: 1 | AC43: 5 | AD43: 1 | AE43: 6 | AF43: 1 | AG43: 1 | AH43: 1 | AI43: N/A | AJ43: N/A
A44: Meijer #056 | B44: Jackson | C44: 10 | D44: 0.9 | E44: 4 | F44: 1 | G44: 4 | H44: 1 | I44: 8 | J44: 1 | K44: 4 | L44: 1 | M44: 3 | N44: 0.67 | O44: N/A | P44: N/A | Q44: N/A | R44: N/A | S44: 1 | T44: 1 | U44: 1 | V44: 1 | W44: 7 | X44: 1 | Y44: 4 | Z44: 1 | AA44: 14 | AB44: 1 | AC44: 7 | AD44: 1 | AE44: 10 | AF44: 1 | AG44: 1 | AH44: 1 | AI44: 3 | AJ44: 1
A45: Meijer #108 | B45: Midland | C45: 10 | D45: 0.9 | E45: 1 | F45: 1 | G45: 5 | H45: 0.8 | I45: N/A | J45: N/A | K45: 5 | L45: 1 | M45: 5 | N45: 1 | O45: N/A | P45: N/A | Q45: N/A | R45: N/A | S45: 1 | T45: 1 | U45: 7 | V45: 1 | W45: 7 | X45: 1 | Y45: 6 | Z45: 1 | AA45: 5 | AB45: 0.8 | AC45: 6 | AD45: 1 | AE45: 9 | AF45: 1 | AG45: 4 | AH45: 1 | AI45: 4 | AJ45: 1
A46: Meijer #119 | B46: Kalamazoo | C46: N/A | D46: N/A | E46: 7 | F46: 0.86 | G46: 3 | H46: 1 | I46: 2 | J46: 1 | K46: N/A | L46: N/A | M46: 3 | N46: 1 | O46: 4 | P46: 1 | Q46: 2 | R46: 1 | S46: 12 | T46: 0.75 | U46: 7 | V46: 0.71 | W46: 15 | X46: 0.8 | Y46: 1 | Z46: 1 | AA46: 6 | AB46: 0.83 | AC46: 3 | AD46: 1 | AE46: 27 | AF46: 0.96 | AG46: 13 | AH46: 0.46 | AI46: 16 | AJ46: 0.63
A47: Meijer #158 | B47: Knapps Corner | C47: 16 | D47: 0.94 | E47: 20 | F47: 0.85 | G47: 6 | H47: 1 | I47: 13 | J47: 1 | K47: 8 | L47: 1 | M47: N/A | N47: N/A | O47: N/A | P47: N/A | Q47: N/A | R47: N/A | S47: 2 | T47: 1 | U47: N/A | V47: N/A | W47: 5 | X47: 1 | Y47: 10 | Z47: 1 | AA47: 10 | AB47: 1 | AC47: 4 | AD47: 1 | AE47: 14 | AF47: 1 | AG47: 10 | AH47: 1 | AI47: 13 | AJ47: 0.92
A48: Meijer #199 | B48: Caledonia | C48: 10 | D48: 0.9 | E48: 12 | F48: 1 | G48: 6 | H48: 1 | I48: 11 | J48: 1 | K48: 1 | L48: 1 | M48: N/A | N48: N/A | O48: N/A | P48: N/A | Q48: N/A | R48: N/A | S48: 3 | T48: 1 | U48: 1 | V48: 1 | W48: 4 | X48: 1 | Y48: 8 | Z48: 0.85 | AA48: 3 | AB48: 0.67 | AC48: 12 | AD48: 1 | AE48: 8 | AF48: 1 | AG48: 19 | AH48: 0.95 | AI48: 11 | AJ48: 1
A49: Meijer #216 | B49: Standale | C49: 8 | D49: 1 | E49: 14 | F49: 0.93 | G49: 4 | H49: 1 | I49: 6 | J49: 1 | K49: 11 | L49: 0.91 | M49: N/A | N49: N/A | O49: 2 | P49: 1 | Q49: N/A | R49: N/A | S49: 4 | T49: 1 | U49: N/A | V49: N/A | W49: 21 | X49: 0.95 | Y49: 6 | Z49: 1 | AA49: 4 | AB49: 1 | AC49: 2 | AD49: 1 | AE49: 2 | AF49: 1 | AG49: 8 | AH49: 0.88 | AI49: 6 | AJ49: 1
...

Sheet Monthly_Summary
A1: Meijer SLA — Monthly Summary
A3: Month | B3: Target SLA | C3: Actual SLA % | D3: Tickets Created | E3: Tickets Met SLA | F3: Tickets Missed SLA | G3: MoM SLA Change | H3: Above/Below Target
A4: =Raw_Data!A6 -> Feb-25 | B4: =Raw_Data!B6 -> 0.85 | C4: =Raw_Data!C6 -> 0.85 | D4: =Raw_Data!D6 -> 1290 | E4: =ROUND(D4*C4,0) -> 1097 | F4: =D4-E4 -> 193 | H4: =IF(C4>=B4,"Above Target","Below Target") -> Above Target
A5: =Raw_Data!A7 -> Mar-25 | B5: =Raw_Data!B7 -> 0.85 | C5: =Raw_Data!C7 -> 0.86 | D5: =Raw_Data!D7 -> 1416 | E5: =ROUND(D5*C5,0) -> 1218 | F5: =D5-E5 -> 198 | G5: =C5-C4 -> 0.01 | H5: =IF(C5>=B5,"Above Target","Below Target") -> Above Target
A6: =Raw_Data!A8 -> Apr-25 | B6: =Raw_Data!B8 -> 0.85 | C6: =Raw_Data!C8 -> 0.87 | D6: =Raw_Data!D8 -> 1225 | E6: =ROUND(D6*C6,0) -> 1066 | F6: =D6-E6 -> 159 | G6: =C6-C5 -> 0.01 | H6: =IF(C6>=B6,"Above Target","Below Target") -> Above Target
A7: =Raw_Data!A9 -> May-25 | B7: =Raw_Data!B9 -> 0.85 | C7: =Raw_Data!C9 -> 0.93 | D7: =Raw_Data!D9 -> 994 | E7: =ROUND(D7*C7,0) -> 924 | F7: =D7-E7 -> 70 | G7: =C7-C6 -> 0.06 | H7: =IF(C7>=B7,"Above Target","Below Target") -> Above Target
A8: =Raw_Data!A10 -> Jun-25 | B8: =Raw_Data!B10 -> 0.85 | C8: =Raw_Data!C10 -> 0.91 | D8: =Raw_Data!D10 -> 725 | E8: =ROUND(D8*C8,0) -> 660 | F8: =D8-E8 -> 65 | G8: =C8-C7 -> -0.02 | H8: =IF(C8>=B8,"Above Target","Below Target") -> Above Target
A9: =Raw_Data!A11 -> Jul-25 | B9: =Raw_Data!B11 -> 0.85 | C9: =Raw_Data!C11 -> 0.93 | D9: =Raw_Data!D11 -> 818 | E9: =ROUND(D9*C9,0) -> 761 | F9: =D9-E9 -> 57 | G9: =C9-C8 -> 0.02 | H9: =IF(C9>=B9,"Above Target","Below Target") -> Above Target
A10: =Raw_Data!A12 -> Aug-25 | B10: =Raw_Data!B12 -> 0.85 | C10: =Raw_Data!C12 -> 0.92 | D10: =Raw_Data!D12 -> 711 | E10: =ROUND(D10*C10,0) -> 654 | F10: =D10-E10 -> 57 | G10: =C10-C9 -> -0.01 | H10: =IF(C10>=B10,"Above Target","Below Target") -> Above Target
A11: =Raw_Data!A13 -> Sep-25 | B11: =Raw_Data!B13 -> 0.85 | C11: =Raw_Data!C13 -> 0.9 | D11: =Raw_Data!D13 -> 828 | E11: =ROUND(D11*C11,0) -> 745 | F11: =D11-E11 -> 83 | G11: =C11-C10 -> -0.02 | H11: =IF(C11>=B11,"Above Target","Below Target") -> Above Target
A12: =Raw_Data!A14 -> Oct-25 | B12: =Raw_Data!B14 -> 0.85 | C12: =Raw_Data!C14 -> 0.92 | D12: =Raw_Data!D14 -> 822 | E12: =ROUND(D12*C12,0) -> 756 | F12: =D12-E12 -> 66 | G12: =C12-C11 -> 0.02 | H12: =IF(C12>=B12,"Above Target","Below Target") -> Above Target
A13: =Raw_Data!A15 -> Nov-25 | B13: =Raw_Data!B15 -> 0.85 | C13: =Raw_Data!C15 -> 0.9 | D13: =Raw_Data!D15 -> 993 | E13: =ROUND(D13*C13,0) -> 894 | F13: =D13-E13 -> 99 | G13: =C13-C12 -> -0.02 | H13: =IF(C13>=B13,"Above Target","Below Target") -> Above Target
A14: =Raw_Data!A16 -> Dec-25 | B14: =Raw_Data!B16 -> 0.85 | C14: =Raw_Data!C16 -> 0.89 | D14: =Raw_Data!D16 -> 1006 | E14: =ROUND(D14*C14,0) -> 895 | F14: =D14-E14 -> 111 | G14: =C14-C13 -> -0.01 | H14: =IF(C14>=B14,"Above Target","Below Target") -> Above Target
A15: =Raw_Data!A17 -> Jan-26 | B15: =Raw_Data!B17 -> 0.85 | C15: =Raw_Data!C17 -> 0.93 | D15: =Raw_Data!D17 -> 1141 | E15: =ROUND(D15*C15,0) -> 1061 | F15: =D15-E15 -> 80 | G15: =C15-C14 -> 0.04 | H15: =IF(C15>=B15,"Above Target","Below Target") -> Above Target
A16: =Raw_Data!A18 -> Feb-26 | B16: =Raw_Data!B18 -> 0.85 | C16: =Raw_Data!C18 -> 0.93 | D16: =Raw_Data!D18 -> 1084 | E16: =ROUND(D16*C16,0) -> 1008 | F16: =D16-E16 -> 76 | G16: =C16-C15 -> 0 | H16: =IF(C16>=B16,"Above Target","Below Target") -> Above Target
... A20: =Raw_Data!A22 -> Jun-26 | B20: =Raw_Data!B22 -> 0.85 | C20: =Raw_Data!C22 -> 0.92 | D20: =Raw_Data!D22 -> 1208 | E20: =ROUND(D20*C20,0) -> 1111 | F20: =D20-E20 -> 97 | G20: =C20-C19 -> -0.02 | H20: =IF(C20>=B20,"Above Target","Below Target") -> Above Target
A23: Key Metrics
A24: Average SLA % | B24: =AVERAGE(C4:C20) -> 0.90882353
A25: Weighted SLA % (ticket-weighted) | B25: =SUMPRODUCT(C4:C20,D4:D20)/SUM(D4:D20) -> 0.9070465
A26: Total Tickets Created | B26: =SUM(D4:D20) -> 17999
A27: Total Tickets Met SLA | B27: =SUM(E4:E20) -> 16326
A28: Total Tickets Missed SLA | B28: =SUM(F4:F20) -> 1673
A29: Months Above Target | B29: =COUNTIF(H4:H20,"Above Target") -> 17
A30: Total Months | B30: =COUNTA(A4:A20) -> 17
A31: % Months Above Target | B31: =COUNTIF(H4:H20,"Above Target")/COUNTA(A4:A20) -> 1
A32: Best Month (SLA) | B32: =INDEX(A4:A20,MATCH(MAX(C4:C20),C4:C20,0)) -> May-26
A33: Best Month SLA % | B33: =MAX(C4:C20) -> 0.94
A34: Worst Month (SLA) | B34: =INDEX(A4:A20,MATCH(MIN(C4:C20),C4:C20,0)) -> Feb-25
A35: Worst Month SLA % | B35: =MIN(C4:C20) -> 0.85

Sheet VIP_Stores
A1: Meijer VIP Store SLA Detail (Feb 2025–Jun 2026)
A3: Store Number | B3: City | C3: Month | D3: Ticket Count | E3: SLA % | F3: Target | G3: Status
A4: Meijer #033 | B4: Traverse City | C4: Feb-25 | D4: 8 | E4: 0.25 | F4: 0.85 | G4: =IF(ISBLANK(D4),"No data",IF(E4>=F4,"Above","Below")) -> Below
A5: Meijer #033 | B5: Traverse City | C5: Mar-25 | D5: 4 | E5: 1 | F5: 0.85 | G5: =IF(ISBLANK(D5),"No data",IF(E5>=F5,"Above","Below")) -> Above
A6: Meijer #033 | B6: Traverse City | C6: Apr-25 | D6: 11 | E6: 0.73 | F6: 0.85 | G6: =IF(ISBLANK(D6),"No data",IF(E6>=F6,"Above","Below")) -> Below
A7: Meijer #033 | B7: Traverse City | C7: May-25 | D7: 3 | E7: 1 | F7: 0.85 | G7: =IF(ISBLANK(D7),"No data",IF(E7>=F7,"Above","Below")) -> Above
A8: Meijer #033 | B8: Traverse City | C8: Jun-25 | D8: 1 | E8: 1 | F8: 0.85 | G8: =IF(ISBLANK(D8),"No data",IF(E8>=F8,"Above","Below")) -> Above
A9: Meijer #033 | B9: Traverse City | C9: Jul-25 | F9: 0.85 | G9: =IF(ISBLANK(D9),"No data",IF(E9>=F9,"Above","Below")) -> No data
A10: Meijer #033 | B10: Traverse City | C10: Aug-25 | F10: 0.85 | G10: =IF(ISBLANK(D10),"No data",IF(E10>=F10,"Above","Below")) -> No data
A11: Meijer #033 | B11: Traverse City | C11: Sep-25 | D11: 2 | E11: 1 | F11: 0.85 | G11: =IF(ISBLANK(D11),"No data",IF(E11>=F11,"Above","Below")) -> Above
A12: Meijer #033 | B12: Traverse City | C12: Oct-25 | D12: 2 | E12: 1 | F12: 0.85 | G12: =IF(ISBLANK(D12),"No data",IF(E12>=F12,"Above","Below")) -> Above
A13: Meijer #033 | B13: Traverse City | C13: Nov-25 | D13: 2 | E13: 1 | F13: 0.85 | G13: =IF(ISBLANK(D13),"No data",IF(E13>=F13,"Above","Below")) -> Above
A14: Meijer #033 | B14: Traverse City | C14: Dec-25 | D14: 2 | E14: 1 | F14: 0.85 | G14: =IF(ISBLANK(D14),"No data",IF(E14>=F14,"Above","Below")) -> Above
A15: Meijer #033 | B15: Traverse City | C15: Jan-26 | D15: 10 | E15: 0.8 | F15: 0.85 | G15: =IF(ISBLANK(D15),"No data",IF(E15>=F15,"Above","Below")) -> Below
A16: Meijer #033 | B16: Traverse City | C16: Feb-26 | D16: 6 | E16: 1 | F16: 0.85 | G16: =IF(ISBLANK(D16),"No data",IF(E16>=F16,"Above","Below")) -> Above
A17: Meijer #033 | B17: Traverse City | C17: Mar-26 | D17: 36 | E17: 0.97 | F17: 0.85 | G17: =IF(ISBLANK(D17),"No data",IF(E17>=F17,"Above","Below")) -> Above
A18: Meijer #033 | B18: Traverse City | C18: Apr-26 | D18: 7 | E18: 0.86 | F18: 0.85 | G18: =IF(ISBLANK(D18),"No data",IF(E18>=F18,"Above","Below")) -> Above
A19: Meijer #033 | B19: Traverse City | C19: May-26 | D19: 1 | E19: 1 | F19: 0.85 | G19: =IF(ISBLANK(D19),"No data",IF(E19>=F19,"Above","Below")) -> Above
A20: Meijer #033 | B20: Traverse City | C20: Jun-26 | D20: 1 | E20: 1 | F20: 0.85 | G20: =IF(ISBLANK(D20),"No data",IF(E20>=F20,"Above","Below")) -> Above
A21: Meijer #047 | B21: Holland | C21: Feb-25 | D21: 2 | E21: 1 | F21: 0.85 | G21: =IF(ISBLANK(D21),"No data",IF(E21>=F21,"Above","Below")) -> Above
A22: Meijer #047 | B22: Holland | C22: Mar-25 | D22: 9 | E22: 1 | F22: 0.85 | G22: =IF(ISBLANK(D22),"No data",IF(E22>=F22,"Above","Below")) -> Above
... A25: Meijer #047 | B25: Holland | C25: Jun-25 | D25: 6 | E25: 0.83 | F25: 0.85 | G25: =IF(ISBLANK(D25),"No data",IF(E25>=F25,"Above","Below")) -> Below
A26: Meijer #047 | B26: Holland | C26: Jul-25 | F26: 0.85 | G26: =IF(ISBLANK(D26),"No data",IF(E26>=F26,"Above","Below")) -> No data
A27: Meijer #047 | B27: Holland | C27: Aug-25 | F27: 0.85 | G27: =IF(ISBLANK(D27),"No data",IF(E27>=F27,"Above","Below")) -> No data
A28: Meijer #047 | B28: Holland | C28: Sep-25 | F28: 0.85 | G28: =IF(ISBLANK(D28),"No data",IF(E28>=F28,"Above","Below")) -> No data
A29: Meijer #047 | B29: Holland | C29: Oct-25 | D29: 1 | E29: 1 | F29: 0.85 | G29: =IF(ISBLANK(D29),"No data",IF(E29>=F29,"Above","Below")) -> Above
A30: Meijer #047 | B30: Holland | C30: Nov-25 | F30: 0.85 | G30: =IF(ISBLANK(D30),"No data",IF(E30>=F30,"Above","Below")) -> No data
A31: Meijer #047 | B31: Holland | C31: Dec-25 | D31: 4 | E31: 1 | F31: 0.85 | G31: =IF(ISBLANK(D31),"No data",IF(E31>=F31,"Above","Below")) -> Above
A32: Meijer #047 | B32: Holland | C32: Jan-26 | D32: 5 | E32: 1 | F32: 0.85 | G32: =IF(ISBLANK(D32),"No data",IF(E32>=F32,"Above","Below")) -> Above
A33: Meijer #047 | B33: Holland | C33: Feb-26 | D33: 10 | E33: 1 | F33: 0.85 | G33: =IF(ISBLANK(D33),"No data",IF(E33>=F33,"Above","Below")) -> Above
A34: Meijer #047 | B34: Holland | C34: Mar-26 | D34: 6 | E34: 1 | F34: 0.85 | G34: =IF(ISBLANK(D34),"No data",IF(E34>=F34,"Above","Below")) -> Above
A35: Meijer #047 | B35: Holland | C35: Apr-26 | D35: 3 | E35: 1 | F35: 0.85 | G35: =IF(ISBLANK(D35),"No data",IF(E35>=F35,"Above","Below")) -> Above
A36: Meijer #047 | B36: Holland | C36: May-26 | D36: 8 | E36: 1 | F36: 0.85 | G36: =IF(ISBLANK(D36),"No data",IF(E36>=F36,"Above","Below")) -> Above
A37: Meijer #047 | B37: Holland | C37: Jun-26 | D37: 2 | E37: 1 | F37: 0.85 | G37: =IF(ISBLANK(D37),"No data",IF(E37>=F37,"Above","Below")) -> Above
A38: Meijer #050 | B38: Cascade | C38: Feb-25 | D38: 22 | E38: 0.86 | F38: 0.85 | G38: =IF(ISBLANK(D38),"No data",IF(E38>=F38,"Above","Below")) -> Above
A39: Meijer #050 | B39: Cascade | C39: Mar-25 | D39: 12 | E39: 0.83 | F39: 0.85 | G39: =IF(ISBLANK(D39),"No data",IF(E39>=F39,"Above","Below")) -> Below
A40: Meijer #050 | B40: Cascade | C40: Apr-25 | D40: 5 | E40: 1 | F40: 0.85 | G40: =IF(ISBLANK(D40),"No data",IF(E40>=F40,"Above","Below")) -> Above
A41: Meijer #050 | B41: Cascade | C41: May-25 | D41: 9 | E41: 1 | F41: 0.85 | G41: =IF(ISBLANK(D41),"No data",IF(E41>=F41,"Above","Below")) -> Above
A42: Meijer #050 | B42: Cascade | C42: Jun-25 | D42: 4 | E42: 0.83 | F42: 0.85 | G42: =IF(ISBLANK(D42),"No data",IF(E42>=F42,"Above","Below")) -> Below
A43: Meijer #050 | B43: Cascade | C43: Jul-25 | F43: 0.85 | G43: =IF(ISBLANK(D43),"No data",IF(E43>=F43,"Above","Below")) -> No data
...

Sheet Pivot_Tables
A1: Meijer SLA — Pivot Summary Tables
A2: Note: Built as live SUMIFS/AVERAGEIFS summary tables (equivalent to PivotTables) so they recalc automatically when Raw_Data changes. To convert to native Excel PivotTables, select Raw_Data and use Insert > PivotTable.
A4: Pivot 1: Monthly SLA Trend
A5: Month | B5: Actual SLA % | C5: Target SLA
A6: =Monthly_Summary!A4 -> Feb-25 | B6: =Monthly_Summary!C4 -> 0.85 | C6: =Monthly_Summary!B4 -> 0.85
A7: =Monthly_Summary!A5 -> Mar-25 | B7: =Monthly_Summary!C5 -> 0.86 | C7: =Monthly_Summary!B5 -> 0.85
A8: =Monthly_Summary!A6 -> Apr-25 | B8: =Monthly_Summary!C6 -> 0.87 | C8: =Monthly_Summary!B6 -> 0.85
A9: =Monthly_Summary!A7 -> May-25 | B9: =Monthly_Summary!C7 -> 0.93 | C9: =Monthly_Summary!B7 -> 0.85
A10: =Monthly_Summary!A8 -> Jun-25 | B10: =Monthly_Summary!C8 -> 0.91 | C10: =Monthly_Summary!B8 -> 0.85
A11: =Monthly_Summary!A9 -> Jul-25 | B11: =Monthly_Summary!C9 -> 0.93 | C11: =Monthly_Summary!B9 -> 0.85
A12: =Monthly_Summary!A10 -> Aug-25 | B12: =Monthly_Summary!C10 -> 0.92 | C12: =Monthly_Summary!B10 -> 0.85
A13: =Monthly_Summary!A11 -> Sep-25 | B13: =Monthly_Summary!C11 -> 0.9 | C13: =Monthly_Summary!B11 -> 0.85
A14: =Monthly_Summary!A12 -> Oct-25 | B14: =Monthly_Summary!C12 -> 0.92 | C14: =Monthly_Summary!B12 -> 0.85
A15: =Monthly_Summary!A13 -> Nov-25 | B15: =Monthly_Summary!C13 -> 0.9 | C15: =Monthly_Summary!B13 -> 0.85
A16: =Monthly_Summary!A14 -> Dec-25 | B16: =Monthly_Summary!C14 -> 0.89 | C16: =Monthly_Summary!B14 -> 0.85
A17: =Monthly_Summary!A15 -> Jan-26 | B17: =Monthly_Summary!C15 -> 0.93 | C17: =Monthly_Summary!B15 -> 0.85
... A22: =Monthly_Summary!A20 -> Jun-26 | B22: =Monthly_Summary!C20 -> 0.92 | C22: =Monthly_Summary!B20 -> 0.85
A25: Pivot 2: Monthly Ticket Volume Trend
A26: Month | B26: Tickets Created | C26: Tickets Met SLA | D26: Tickets Missed SLA
A27: =Monthly_Summary!A4 -> Feb-25 | B27: =Monthly_Summary!D4 -> 1290 | C27: =Monthly_Summary!E4 -> 1097 | D27: =Monthly_Summary!F4 -> 193
A28: =Monthly_Summary!A5 -> Mar-25 | B28: =Monthly_Summary!D5 -> 1416 | C28: =Monthly_Summary!E5 -> 1218 | D28: =Monthly_Summary!F5 -> 198
A29: =Monthly_Summary!A6 -> Apr-25 | B29: =Monthly_Summary!D6 -> 1225 | C29: =Monthly_Summary!E6 -> 1066 | D29: =Monthly_Summary!F6 -> 159
A30: =Monthly_Summary!A7 -> May-25 | B30: =Monthly_Summary!D7 -> 994 | C30: =Monthly_Summary!E7 -> 924 | D30: =Monthly_Summary!F7 -> 70
A31: =Monthly_Summary!A8 -> Jun-25 | B31: =Monthly_Summary!D8 -> 725 | C31: =Monthly_Summary!E8 -> 660 | D31: =Monthly_Summary!F8 -> 65
A32: =Monthly_Summary!A9 -> Jul-25 | B32: =Monthly_Summary!D9 -> 818 | C32: =Monthly_Summary!E9 -> 761 | D32: =Monthly_Summary!F9 -> 57
A33: =Monthly_Summary!A10 -> Aug-25 | B33: =Monthly_Summary!D10 -> 711 | C33: =Monthly_Summary!E10 -> 654 | D33: =Monthly_Summary!F10 -> 57
A34: =Monthly_Summary!A11 -> Sep-25 | B34: =Monthly_Summary!D11 -> 828 | C34: =Monthly_Summary!E11 -> 745 | D34: =Monthly_Summary!F11 -> 83
A35: =Monthly_Summary!A12 -> Oct-25 | B35: =Monthly_Summary!D12 -> 822 | C35: =Monthly_Summary!E12 -> 756 | D35: =Monthly_Summary!F12 -> 66
A36: =Monthly_Summary!A13 -> Nov-25 | B36: =Monthly_Summary!D13 -> 993 | C36: =Monthly_Summary!E13 -> 894 | D36: =Monthly_Summary!F13 -> 99
A37: =Monthly_Summary!A14 -> Dec-25 | B37: =Monthly_Summary!D14 -> 1006 | C37: =Monthly_Summary!E14 -> 895 | D37: =Monthly_Summary!F14 -> 111
A38: =Monthly_Summary!A15 -> Jan-26 | B38: =Monthly_Summary!D15 -> 1141 | C38: =Monthly_Summary!E15 -> 1061 | D38: =Monthly_Summary!F15 -> 80
... A43: =Monthly_Summary!A20 -> Jun-26 | B43: =Monthly_Summary!D20 -> 1208 | C43: =Monthly_Summary!E20 -> 1111 | D43: =Monthly_Summary!F20 -> 97
A46: Pivot 3: VIP Store Comparison
A47: Store Number | B47: City | C47: Total Tickets | D47: Average SLA %
A48: =VIP_Stores!A178 -> Meijer #033 | B48: =VIP_Stores!B178 -> Traverse City | C48: =VIP_Stores!C178 -> 96 | D48: =VIP_Stores!D178 -> 0.86427083
A49: =VIP_Stores!A179 -> Meijer #047 | B49: =VIP_Stores!B179 -> Holland | C49: =VIP_Stores!C179 -> 63 | D49: =VIP_Stores!D179 -> 0.98380952
A50: =VIP_Stores!A180 -> Meijer #050 | B50: =VIP_Stores!B180 -> Cascade | C50: =VIP_Stores!C180 -> 73 | D50: =VIP_Stores!D180 -> 0.92054795
A51: =VIP_Stores!A181 -> Meijer #056 | B51: =VIP_Stores!B181 -> Jackson | C51: =VIP_Stores!C181 -> 81 | D51: =VIP_Stores!D181 -> 0.9754321
A52: =VIP_Stores!A182 -> Meijer #108 | B52: =VIP_Stores!B182 -> Midland | C52: =VIP_Stores!C182 -> 75 | D52: =VIP_Stores!D182 -> 0.96
A53: =VIP_Stores!A183 -> Meijer #119 | B53: =VIP_Stores!B183 -> Kalamazoo | C53: =VIP_Stores!C183 -> 121 | D53: =VIP_Stores!D183 -> 0.80123967
...
